Workbook
Name AA: #REF!
Name JD: #REF!
Name 一般贸易: #REF!
Name addresses: #REF!
Name AA: #REF!
Name 一般贸易: #REF!
Name AA: #REF!
Name 一般贸易: #REF!
Name AA: #REF!
Name 一般贸易: #REF!
Name AA: #REF!
Name 一般贸易: #REF!
Name AA: #REF!
Name 一般贸易: #REF!
Name AA: #REF!
Name 一般贸易: #REF!

Sheet 已到ARRIVED
A1: 序号 serial number | B1: 中国HSCODE（China） | C1: 印尼HS CODE (Indonesia) | D1: 货号 Item No. | E1: 产品中文名称 Chinese name of the product | F1: 产品英文名称 English name of the product | G1: 规格 specification | H1: 用量 dosage | I1: 单位 Unit | J1: 需求数量 Quantity | K1: 产品数量Product quantity | L1: 单位 Unit | M1: 供应商 Supplier | N1: 采购单日期 Date of purchase order | O1: 采购单号 PO No. | P1: 采购单价 Purchase price | Q1: 采购金额Purchase Amount | R1: 采购总额 Total Amount | S1: 单个毛重 Gross weight（KGM） | T1: 毛重总重 Total Gross weight（KGM） | U1: 单个净重 Net weight（KGM） | V1: 净重总重Total Net weight（KGM） | W1: 卡板号 Pallet No. | X1: 箱号 Carton No. | Y1: 箱数 Carton No. | Z1: 每箱数量Qty/Per carton | AA1: 长 Length | AB1: 宽 Width | AC1: 高 Height | AD1: 立方数/每箱CBM/Per carton | AE1: 总立方数Total CBM | AF1: 图片 Picture | AG1: 产品用途 product use | AH1: 合同号码 Contract No. | AI1: 合同日期 Date of contract | AJ1: 发票号 Invoice No. | AK1: 发票日期 Date of Invoice | AL1: 发票单价 Unit price on invoice | AM1: 金额 Invoice amount | AN1: 发票合计金额Invoice total amount | AO1: 产品数量Product quantity | AP1: 单位 Unit | AQ1: 柜号 Container No. | AR1: 走柜日期 Shipping date | AS1: 提单号 Bl No. | AT1: 预计到港日期 ETA PORT | AU1: 实际到厂日期 Actual arrival date | AV1: Container Size | AW1: Vessel Name/Voyage No. | AX1: 总集装箱运费金额（中国运费） Total Container Freight Amount (China's Freight) | AY1: 货运代理运输费用 Forwarder Transportation Costs (Indonesia Freight) | AZ1: Actual freight for product
A2: 1 | B2: 3923900000 | C2: 392390 | E2: 塑胶件-折叠筐 | F2: folding basket | I2: PCE | J2: 4400 | K2: 4400 | L2: pcs | M2: BRIGHT STAR (HK)INDUSTRY/LIMITED | P2: 56 | Q2: 246400 | R2: 246400 | T2: 10620 | V2: 10296 | W2: 1-22 | X2: 1-22 | Y2: 22 | Z2: 200 | AA2: 119 | AB2: 99 | AC2: 243 | AD2: 2.8610896 | AE2: 62.94 | AF2: =_xlfn.DISPIMG("ID_6B6B16C4FA4B4B8B89694FFDC87BFBE3",1) -> =DISPIMG("ID_6B6B16C4FA4B4B8B89694FFDC87BFBE3",1) | AH2: RPRRI00139 | AI2: 45996 | AJ2: PR202400139 | AK2: 45996 | AL2: 56 | AM2: 246400 | AN2: 246400 | AO2: 4400 | AP2: pcs | AQ2: WHSU6160759 | AR2: 45659 | AS2: 030F500038 | AT2: 45674 | AU2: 45677 | AV2: 40HQ | AW2: WAN HAI 371/S011 | AX2: 16188 | AZ2: ¥212,872.84
Q3: 246400 | R3: 246400 | T3: 10620 | V3: 10296 | Y3: 22 | AE3: 62.94 | AM3: 246400 | AN3: 246400
R5: 总合计 | T5: 10620 | V5: 10296 | Y5: 22 | AE5: 62.94 | AM5: 246400 | AN5: 246400
A6: 1 | B6: 3923900000 | C6: 392390 | E6: 塑胶件-折叠筐 | F6: folding basket | I6: PCE | J6: 4400 | K6: 4400 | L6: pcs | M6: BRIGHT STAR (HK)INDUSTRY/LIMITED | P6: 56 | Q6: 246400 | R6: 246400 | T6: 10560 | V6: 10296 | W6: 1-22 | X6: 1-22 | Y6: 22 | Z6: 200 | AA6: 119 | AB6: 99 | AC6: 243 | AD6: 2.8610896 | AE6: 62.94 | AF6: =_xlfn.DISPIMG("ID_6B6B16C4FA4B4B8B89694FFDC87BFBE3",1) -> =DISPIMG("ID_6B6B16C4FA4B4B8B89694FFDC87BFBE3",1) | AH6: RPRRI00140 | AI6: 45631 | AJ6: PR202400140 | AK6: 45631 | AL6: 56 | AM6: 246400 | AN6: 246400 | AO6: 4400 | AP6: pcs | AQ6: WHSU5417230 | AR6: 45660 | AS6: 030F500039 | AT6: 45674 | AU6: 45677 | AV6: 40HQ | AW6: WAN HAI 371/S011 | AX6: 16188 | AZ6: ¥212,872.84
Q7: 246400 | R7: 246400 | T7: 10560 | V7: 10296 | Y7: 22 | AE7: 62.94 | AM7: 246400 | AN7: 246400
R9: 总合计 | T9: 10560 | V9: 10296 | Y9: 22 | AE9: 62.94 | AM9: 246400 | AN9: 246400
A10: 1 | B10: 8480790090 | C10: 848079 | D10: J00002-Jack Lantern-南瓜灯 | E10: 工具灯IC板打螺丝底模 | F10: Tool light IC board screw bottom die | I10: PCE | J10: 4 | K10: 4 | L10: pcs | M10: 河源市源城区新汇丰机械模具加工部 | P10: 120 | Q10: 480 | R10: 26320 | T10: 0.97 | V10: 0.91 | W10: 2 | X10: 序号1 | Y10: 1 | Z10: 4 | AD10: 0 | AE10: 0.1 | AF10: =_xlfn.DISPIMG("ID_8FE94ACA647642CD956D85F203645F70",1) -> =DISPIMG("ID_8FE94ACA647642CD956D85F203645F70",1) | AH10: RPRRI00146 | AI10: 45631 | AJ10: PR202400146 | AK10: 45631 | AL10: 120 | AM10: 480 | AN10: 13830 | AO10: 4 | AP10: pcs | AQ10: WHSU2789070 | AR10: 45660 | AS10: 030F500175 | AT10: 45674 | AU10: 45677 | AV10: 20FT | AW10: WAN HAI 371/S011 | AX10: ¥9,738.00 | AZ10: ¥351,329.77
A11: 2 | B11: 8480790090 | C11: 848079 | D11: J00002-Jack Lantern-南瓜灯 | E11: 工具灯压电池片上下模 | F11: The tool light presses the upper and lower die of the battery | I11: PCE | J11: 2 | K11: 2 | L11: pcs | P11: 700 | Q11: 1400 | T11: 3.36 | V11: 3.3 | Z11: 2 | AF11: =_xlfn.DISPIMG("ID_F0EA65887D414FBD88E7003B0A02AFF3",1) -> =DISPIMG("ID_F0EA65887D414FBD88E7003B0A02AFF3",1) | AL11: 700 | AM11: 1400 | AO11: 2 | AP11: pcs | AQ11: WHSU2789070 | AR11: 45660 | AS11: 030F500175 | AT11: 45674 | AU11: 45677 | AV11: 20FT | AW11: WAN HAI 371/S011
A12: 3 | B12: 9405990000 | C12: 940599 | D12: J00002-Jack Lantern-南瓜灯 | E12: 假电池 | F12: Dummy cell | I12: PCE | J12: 2 | K12: 2 | L12: pcs | P12: 110 | Q12: 220 | T12: 1.32 | V12: 1.26 | Z12: 2 | AF12: =_xlfn.DISPIMG("ID_C2634432D5F8470D94EBC8DCEA3AC690",1) -> =DISPIMG("ID_C2634432D5F8470D94EBC8DCEA3AC690",1) | AL12: 110 | AM12: 220 | AO12: 2 | AP12: pcs | AQ12: WHSU2789070 | AR12: 45660 | AS12: 030F500175 | AT12: 45674 | AU12: 45677 | AV12: 20FT | AW12: WAN HAI 371/S011
A13: 4 | B13: 8480790090 | C13: 848079 | D13: J00002-Jack Lantern-南瓜灯 | E13: 南瓜锥超声上模 | F13: Ultrasonic molding of pumpkin cone | I13: PCE | J13: 2 | K13: 2 | L13: pcs | P13: 500 | Q13: 1000 | T13: 1.86 | V13: 1.8 | Z13: 2 | AF13: =_xlfn.DISPIMG("ID_CF02C89252324C018514166078A94805",1) -> =DISPIMG("ID_CF02C89252324C018514166078A94805",1) | AL13: 500 | AM13: 1000 | AO13: 2 | AP13: pcs | AQ13: WHSU2789070 | AR13: 45660 | AS13: 030F500175 | AT13: 45674 | AU13: 45677 | AV13: 20FT | AW13: WAN HAI 371/S011
A14: 5 | B14: 8480790090 | C14: 848079 | D14: J00002-Jack Lantern-南瓜灯 | E14: 南瓜锥超声下模 | F14: Pumpkin cone ultrasonic mold | I14: PCE | J14: 2 | K14: 2 | L14: pcs | P14: 500 | Q14: 1000 | T14: 0.76 | V14: 0.7 | Z14: 2 | AF14: =_xlfn.DISPIMG("ID_745DB565B82B4711AA974B3E3591D4E1",1) -> =DISPIMG("ID_745DB565B82B4711AA974B3E3591D4E1",1) | AL14: 500 | AM14: 1000 | AO14: 2 | AP14: pcs | AQ14: WHSU2789070 | AR14: 45660 | AS14: 030F500175 | AT14: 45674 | AU14: 45677 | AV14: 20FT | AW14: WAN HAI 371/S011
A15: 6 | B15: 8480790090 | C15: 848079 | D15: J00025-Color Changing Pumpkin Light-变色南瓜灯 | E15: 压电池片上下模 | F15: Press the upper and lower die of the battery | I15: PCE | J15: 2 | K15: 2 | L15: pcs | P15: 475 | Q15: 950 | T15: 2.56 | V15: 2.5 | Z15: 2 | AF15: =_xlfn.DISPIMG("ID_32A27F73F46047C8969CD2866D9955D3",1) -> =DISPIMG("ID_32A27F73F46047C8969CD2866D9955D3",1) | AL15: 475 | AM15: 950 | AO15: 2 | AP15: pcs | AQ15: WHSU2789070 | AR15: 45660 | AS15: 030F500175 | AT15: 45674 | AU15: 45677 | AV15: 20FT | AW15: WAN HAI 371/S011
A16: 7 | B16: 8480790090 | C16: 848079 | D16: J00025-Color Changing Pumpkin Light-变色南瓜灯 | E16: 三档开关烫胶固定底模 | F16: Three speed switch hot glue fixed bottom die | I16: PCE | J16: 1 | K16: 1 | L16: pcs | P16: 160 | Q16: 160 | T16: 0.5 | V16: 0.44 | Z16: 1 | AF16: =_xlfn.DISPIMG("ID_0B5834FE48B24586813C530B349AC09B",1) -> =DISPIMG("ID_0B5834FE48B24586813C530B349AC09B",1) | AL16: 160 | AM16: 160 | AO16: 1 | AP16: pcs | AQ16: WHSU2789070 | AR16: 45660 | AS16: 030F500175 | AT16: 45674 | AU16: 45677 | AV16: 20FT | AW16: WAN HAI 371/S011
A17: 8 | B17: 8480790090 | C17: 848079 | D17: J00025-Color Changing Pumpkin Light-变色南瓜灯 | E17: 南瓜灯打螺丝底模 | F17: Jack-o '-lantern screw bottom mold | I17: PCE | J17: 6 | K17: 6 | L17: pcs | P17: 160 | Q17: 960 | T17: 2.22 | V17: 2.16 | Z17: 6 | AF17: =_xlfn.DISPIMG("ID_AA5B34CBC225478795798F5B047E221C",1) -> =DISPIMG("ID_AA5B34CBC225478795798F5B047E221C",1) | AL17: 160 | AM17: 960 | AO17: 6 | AP17: pcs | AQ17: WHSU2789070 | AR17: 45660 | AS17: 030F500175 | AT17: 45674 | AU17: 45677 | AV17: 20FT | AW17: WAN HAI 371/S011
A18: 9 | B18: 8480790090 | C18: 848079 | D18: J00025-Color Changing Pumpkin Light-变色南瓜灯 | E18: 电池盖打螺丝底模 | F18: Screw the bottom mold of the battery cover | I18: PCE | J18: 1 | K18: 1 | L18: pcs | P18: 160 | Q18: 160 | T18: 0.44 | V18: 0.38 | Z18: 1 | AF18: =_xlfn.DISPIMG("ID_FB614F5E6C6C4DA695E98E76D90969E3",1) -> =DISPIMG("ID_FB614F5E6C6C4DA695E98E76D90969E3",1) | AL18: 160 | AM18: 160 | AO18: 1 | AP18: pcs | AQ18: WHSU2789070 | AR18: 45660 | AS18: 030F500175 | AT18: 45674 | AU18: 45677 | AV18: 20FT | AW18: WAN HAI 371/S011
A19: 10 | B19: 9405990000 | C19: 940599 | D19: J00025-Color Changing Pumpkin Light-变色南瓜灯 | E19: 假电池 | F19: Dummy cell | I19: PCE | J19: 3 | K19: 3 | L19: pcs | P19: 130 | Q19: 390 | T19: 1.68 | V19: 1.62 | Z19: 3 | AF19: =_xlfn.DISPIMG("ID_2F549D4391284DE89FA5AF61D8FFBEBE",1) -> =DISPIMG("ID_2F549D4391284DE89FA5AF61D8FFBEBE",1) | AL19: 130 | AM19: 390 | AO19: 3 | AP19: pcs | AQ19: WHSU2789070 | AR19: 45660 | AS19: 030F500175 | AT19: 45674 | AU19: 45677 | AV19: 20FT | AW19: WAN HAI 371/S011
A20: 11 | B20: 8480790090 | C20: 848079 | D20: J00012-Little Pumpkin Lamp-小南瓜灯 | E20: 压电池片上下模 | F20: Press the upper and lower die of the battery | I20: PCE | J20: 2 | K20: 2 | L20: pcs | P20: 525 | Q20: 1050 | T20: 1.96 | V20: 1.9 | Z20: 2 | AF20: =_xlfn.DISPIMG("ID_874FB425E2B142E5831E2C22D2A0C7DB",1) -> =DISPIMG("ID_874FB425E2B142E5831E2C22D2A0C7DB",1) | AL20: 525 | AM20: 1050 | AO20: 2 | AP20: pcs | AQ20: WHSU2789070 | AR20: 45660 | AS20: 030F500175 | AT20: 45674 | AU20: 45677 | AV20: 20FT | AW20: WAN HAI 371/S011
A21: 12 | B21: 8480790090 | C21: 848079 | D21: J00012-Little Pumpkin Lamp-小南瓜灯 | E21: 打螺丝底模 | F21: Screw the bottom die | I21: PCE | J21: 6 | K21: 6 | L21: pcs | P21: 300 | Q21: 1800 | T21: 3.54 | V21: 3.48 | Z21: 6 | AF21: =_xlfn.DISPIMG("ID_AC2CE519F2DA48B8BE1152F4470C1397",1) -> =DISPIMG("ID_AC2CE519F2DA48B8BE1152F4470C1397",1) | AL21: 300 | AM21: 1800 | AO21: 6 | AP21: pcs | AQ21: WHSU2789070 | AR21: 45660 | AS21: 030F500175 | AT21: 45674 | AU21: 45677 | AV21: 20FT | AW21: WAN HAI 371/S011
A22: 13 | B22: 8480790090 | C22: 848079 | D22: J00012-Little Pumpkin Lamp-小南瓜灯 | E22: 电池盖打螺丝底模 | F22: Screw the bottom mold of the battery cover | I22: PCE | J22: 1 | K22: 2 | L22: pcs | P22: 160 | Q22: 160 | T22: 0.32 | V22: 0.26 | Z22: 2 | AF22: =_xlfn.DISPIMG("ID_5DF9D5C8671B44538AC5D5471D0F5F4F",1) -> =DISPIMG("ID_5DF9D5C8671B44538AC5D5471D0F5F4F",1) | AL22: 160 | AM22: 160 | AO22: 2 | AP22: pcs | AQ22: WHSU2789070 | AR22: 45660 | AS22: 030F500175 | AT22: 45674 | AU22: 45677 | AV22: 20FT | AW22: WAN HAI 371/S011
A23: 14 | B23: 9405990000 | C23: 940599 | D23: J00012-Little Pumpkin Lamp-小南瓜灯 | E23: 假电池 | F23: Dummy cell | I23: PCE | J23: 3 | K23: 3 | L23: pcs | P23: 130 | Q23: 390 | T23: 1.47 | V23: 1.41 | Z23: 3 | AF23: =_xlfn.DISPIMG("ID_E36A17B71E7E4BC687D67895DFDC1011",1) -> =DISPIMG("ID_E36A17B71E7E4BC687D67895DFDC1011",1) | AL23: 130 | AM23: 390 | AO23: 3 | AP23: pcs | AQ23: WHSU2789070 | AR23: 45660 | AS23: 030F500175 | AT23: 45674 | AU23: 45677 | AV23: 20FT | AW23: WAN HAI 371/S011
A24: 15 | B24: 8480790090 | C24: 848079 | D24: W83669-Lighting Ground Plug Arm-亮灯地插手臂 | E24: 手臂L件啤钉轴 | F24: Arm L piece pin shaft | I24: PCE | J24: 1 | K24: 1 | L24: pcs | P24: 460 | Q24: 460 | T24: 0.83 | V24: 0.77 | Z24: 1 | AF24: =_xlfn.DISPIMG("ID_CB076EEA3F11448FB6EFD66B270BAB7C",1) -> =DISPIMG("ID_CB076EEA3F11448FB6EFD66B270BAB7C",1) | AL24: 460 | AM24: 460 | AO24: 1 | AP24: pcs | AQ24: WHSU2789070 | AR24: 45660 | AS24: 030F500175 | AT24: 45674 | AU24: 45677 | AV24: 20FT | AW24: WAN HAI 371/S011
A25: 16 | B25: 8480790090 | C25: 848079 | D25: W83669-Lighting Ground Plug Arm-亮灯地插手臂 | E25: 手臂R件啤钉轴 | F25: Arm R piece stud shaft | I25: PCE | J25: 2 | K25: 2 | L25: pcs | P25: 460 | Q25: 920 | T25: 1.6 | V25: 1.54 | Z25: 2 | AF25: =_xlfn.DISPIMG("ID_2612B1D56C7A4C79A70B63CC3389FE42",1) -> =DISPIMG("ID_2612B1D56C7A4C79A70B63CC3389FE42",1) | AL25: 460 | AM25: 920 | AO25: 2 | AP25: pcs | AQ25: WHSU2789070 | AR25: 45660 | AS25: 030F500175 | AT25: 45674 | AU25: 45677 | AV25: 20FT | AW25: WAN HAI 371/S011
A26: 17 | B26: 8480790090 | C26: 848079 | D26: W83669-Lighting Ground Plug Arm-亮灯地插手臂 | E26: L件打螺丝底模 | F26: L part screw bottom die | I26: PCE | J26: 2 | K26: 2 | L26: pcs | P26: 300 | Q26: 600 | T26: 2.46 | V26: 2.4 | Z26: 2 | AF26: =_xlfn.DISPIMG("ID_BCE0AF53F03A4CDBB66CC875E432543D",1) -> =DISPIMG("ID_BCE0AF53F03A4CDBB66CC875E432543D",1) | AL26: 300 | AM26: 600 | AO26: 2 | AP26: pcs | AQ26: WHSU2789070 | AR26: 45660 | AS26: 030F500175 | AT26: 45674 | AU26: 45677 | AV26: 20FT | AW26: WAN HAI 371/S011
A27: 18 | B27: 8480790090 | C27: 848079 | D27: W83669-Lighting Ground Plug Arm-亮灯地插手臂 | E27: R件打螺丝底模 | F27: Screw bottom die for R pieces | I27: PCE | J27: 4 | K27: 4 | L27: pcs | P27: 320 | Q27: 1280 | T27: 3.66 | V27: 3.6 | Z27: 4 | AF27: =_xlfn.DISPIMG("ID_5B37FD293022479AB7094F4A3BAF3335",1) -> =DISPIMG("ID_5B37FD293022479AB7094F4A3BAF3335",1) | AL27: 320 | AM27: 1280 | AO27: 4 | AP27: pcs | AQ27: WHSU2789070 | AR27: 45660 | AS27: 030F500175 | AT27: 45674 | AU27: 45677 | AV27: 20FT | AW27: WAN HAI 371/S011
A28: 19 | B28: 9405990000 | C28: 940599 | D28: W83669-Lighting Ground Plug Arm-亮灯地插手臂 | E28: 假电池 | F28: Dummy cell | I28: PCE | J28: 3 | K28: 3 | L28: pcs | P28: 150 | Q28: 450 | T28: 9.66 | V28: 9.6 | Z28: 3 | AF28: =_xlfn.DISPIMG("ID_AE927983D05D414FA7ECC092712BE40B",1) -> =DISPIMG("ID_AE927983D05D414FA7ECC092712BE40B",1) | AL28: 150 | AM28: 450 | AO28: 3 | AP28: pcs | AQ28: WHSU2789070 | AR28: 45660 | AS28: 030F500175 | AT28: 45674 | AU28: 45677 | AV28: 20FT | AW28: WAN HAI 371/S011
A29: 20 | B29: 8480790090 | C29: 848079 | D29: J00038-Remote Control Light-遥控灯 | E29: 压电池片上下模 | F29: Press the upper and lower die of the battery | I29: PCE | J29: 2 | K29: 2 | L29: pcs | P29: 700 | Q29: 1400 | T29: 3.36 | V29: 3.3 | Z29: 2 | AF29: =_xlfn.DISPIMG("ID_A60754604D9845D092C090C02088DE3B",1) -> =DISPIMG("ID_A60754604D9845D092C090C02088DE3B",1) | AH29: RPRRI00147 | AI29: 45631 | AJ29: PR202400147 | AK29: 45631 | AL29: 700 | AM29: 1400 | AN29: 12490 | AO29: 2 | AP29: pcs | AQ29: WHSU2789070 | AR29: 45660 | AS29: 030F500175 | AT29: 45674 | AU29: 45677 | AV29: 20FT | AW29: WAN HAI 371/S011
A30: 21 | B30: 8480790090 | C30: 848079 | D30: J00038-Remote Control Light-遥控灯 | E30: 电池盖打螺丝底模 | F30: Screw the bottom mold of the battery cover | I30: PCE | J30: 1 | K30: 1 | L30: pcs | P30: 160 | Q30: 160 | T30: 0.43 | V30: 0.37 | Z30: 1 | AF30: =_xlfn.DISPIMG("ID_A8DE022D494E4CA58B27116046E35C5C",1) -> =DISPIMG("ID_A8DE022D494E4CA58B27116046E35C5C",1) | AL30: 160 | AM30: 160 | AO30: 1 | AP30: pcs | AQ30: WHSU2789070 | AR30: 45660 | AS30: 030F500175 | AT30: 45674 | AU30: 45677 | AV30: 20FT | AW30: WAN HAI 371/S011
A31: 22 | B31: 8480790090 | C31: 848079 | D31: J00038-Remote Control Light-遥控灯 | E31: 打螺丝底模 | F31: Screw the bottom die | I31: PCE | J31: 6 | K31: 6 | L31: pcs | P31: 260 | Q31: 1560 | T31: 1.86 | V31: 1.8 | Z31: 6 | AF31: =_xlfn.DISPIMG("ID_842636CCA3A9420F97B9D38FAB5398E4",1) -> =DISPIMG("ID_842636CCA3A9420F97B9D38FAB5398E4",1) | AL31: 260 | AM31: 1560 | AO31: 6 | AP31: pcs | AQ31: WHSU2789070 | AR31: 45660 | AS31: 030F500175 | AT31: 45674 | AU31: 45677 | AV31: 20FT | AW31: WAN HAI 371/S011
A32: 23 | B32: 9405990000 | C32: 940599 | D32: J00038-Remote Control Light-遥控灯 | E32: 假电池 | F32: Dummy cell | I32: PCE | J32: 3 | K32: 3 | L32: pcs | P32: 140 | Q32: 420 | T32: 1.94 | V32: 1.89 | Z32: 3 | AF32: =_xlfn.DISPIMG("ID_82D82D5E0FF14328BD66F7157A7977B9",1) -> =DISPIMG("ID_82D82D5E0FF14328BD66F7157A7977B9",1) | AL32: 140 | AM32: 420 | AO32: 3 | AP32: pcs | AQ32: WHSU2789070 | AR32: 45660 | AS32: 030F500175 | AT32: 45674 | AU32: 45677 | AV32: 20FT | AW32: WAN HAI 371/S011
A33: 24 | B33: 8480790090 | C33: 848079 | D33: J00002-Jack Lantern-南瓜灯 | E33: 吸塑模 | F33: Blister die | I33: PCE | J33: 4 | K33: 4 | L33: pcs | P33: 380 | Q33: 1520 | T33: 3.47 | V33: 3.12 | X33: 序号2 | Y33: 1 | Z33: 4 | AD33: 0 | AE33: 0.05 | AF33: =_xlfn.DISPIMG("ID_353C71C1CBCF4AAB91E96F2A91B2086B",1) -> =DISPIMG("ID_353C71C1CBCF4AAB91E96F2A91B2086B",1) | AL33: 380 | AM33: 1520 | AO33: 4 | AP33: pcs | AQ33: WHSU2789070 | AR33: 45660 | AS33: 030F500175 | AT33: 45674 | AU33: 45677 | AV33: 20FT | AW33: WAN HAI 371/S011
A34: 25 | B34: 8516800000 | C34: 851680 | D34: J00002-Jack Lantern-南瓜灯 | E34: 发热片 | F34: Heating sheet | I34: PCE | J34: 20 | K34: 20 | L34: pcs | P34: 25 | Q34: 500 | T34: 0.47 | V34: 0.12 | Z34: 20 | AF34: =_xlfn.DISPIMG("ID_99402CBAEFA74B30B46EAADD916293AC",1) -> =DISPIMG("ID_99402CBAEFA74B30B46EAADD916293AC",1) | AL34: 25 | AM34: 500 | AO34: 20 | AP34: pcs | AQ34: WHSU2789070 | AR34: 45660 | AS34: 030F500175 | AT34: 45674 | AU34: 45677 | AV34: 20FT | AW34: WAN HAI 371/S011
A35: 26 | B35: 8480790090 | C35: 848079 | D35: J00002-Jack Lantern-南瓜灯 | E35: 吸塑模 | F35: Blister die | I35: PCE | J35: 6 | K35: 6 | L35: pcs | P35: 380 | Q35: 2280 | T35: 6.35 | V35: 6 | Z35: 6 | AF35: =_xlfn.DISPIMG("ID_9DB3E0628C6C482E97694BE6D94B66A2",1) -> =DISPIMG("ID_9DB3E0628C6C482E97694BE6D94B66A2",1) | AL35: 380 | AM35: 2280 | AO35: 6 | AP35: pcs | AQ35: WHSU2789070 | AR35: 45660 | AS35: 030F500175 | AT35: 45674 | AU35: 45677 | AV35: 20FT | AW35: WAN HAI 371/S011
A36: 27 | B36: 8516800000 | C36: 851680 | D36: J00002-Jack Lantern-南瓜灯 | E36: 发热片 | F36: Heating sheet | I36: PCE | J36: 30 | K36: 30 | L36: pcs | P36: 35 | Q36: 1050 | T36: 0.61 | V36: 0.26 | Z36: 30 | AF36: =_xlfn.DISPIMG("ID_6F35E7324FE241CF9740B1F58C1901C3",1) -> =DISPIMG("ID_6F35E7324FE241CF9740B1F58C1901C3",1) | AL36: 35 | AM36: 1050 | AO36: 30 | AP36: pcs | AQ36: WHSU2789070 | AR36: 45660 | AS36: 030F500175 | AT36: 45674 | AU36: 45677 | AV36: 20FT | AW36: WAN HAI 371/S011
A37: 28 | B37: 8480790090 | C37: 848079 | D37: J00035-Tools Series-工具系列 | E37: 彩钉切水口上下模 | F37: Color nail cut water top and bottom die | I37: PCE | J37: 2 | K37: 2 | L37: pcs | P37: 1800 | Q37: 3600 | T37: 4.9 | V37: 4 | X37: 序号3 | Y37: 1 | Z37: 2 | AD37: 0 | AE37: 0.04 | AF37: =_xlfn.DISPIMG("ID_C553DC26AFCF43389914D771C3A2228C",1) -> =DISPIMG("ID_C553DC26AFCF43389914D771C3A2228C",1) | AL37: 1800 | AM37: 3600 | AO37: 2 | AP37: pcs | AQ37: WHSU2789070 | AR37: 45660 | AS37: 030F500175 | AT37: 45674 | AU37: 45677 | AV37: 20FT | AW37: WAN HAI 371/S011
J38: 123 | Q38: 26320 | R38: 26320 | T38: 64.56 | V38: 60.89 | Y38: 3 | AE38: 0.19 | AM38: 26320 | AN38: 26320
A39: 29 | B39: 7326909000 | C39: 731829 | D39: J00016-Ladle Set-大勺套装 | E39: 2.5x5.5光轴 | F39: 2.5x5.5 optical axis | I39: KGM | J39: 8 | K39: 40000 | L39: PCE | M39: 河源市港正五金制造有限公司 | P39: 75 | Q39: 600 | R39: 141009.77 | T39: 8.47 | V39: 8 | W39: 1 | X39: 序号1 | Y39: 1 | Z39: 序号1箱装4万颗 | AD39: 0 | AE39: 0.02 | AF39: =_xlfn.DISPIMG("ID_F8D7BD56BD9C4739BA64128F900B7C0C",1) -> =DISPIMG("ID_F8D7BD56BD9C4739BA64128F900B7C0C",1) | AH39: RPRRI00148 | AI39: 45631 | AJ39: PR202400148 | AK39: 45631 | AL39: 75 | AM39: 600 | AN39: 126558.19 | AO39: 40000 | AP39: PCE | AQ39: WHSU2789070 | AR39: 45660 | AS39: 030F500175 | AT39: 45674 | AU39: 45677 | AV39: 20FT | AW39: WAN HAI 371/S011 | AX39: ¥9,738.00 | AZ39: 351329.77
A40: 30 | B40: 7326909000 | C40: 732690 | D40: J00016-Ladle Set-大勺套装 | E40: 1.0t*ID2.7*∅18*打孔轮 | F40: 1.0t*ID2.7*∅18* Punch wheel | I40: KGM | J40: 58.9 | K40: 40000 | L40: PCE | P40: 158.3 | Q40: 9323.87 | T40: 59.39 | V40: 58.9 | X40: 序号2 | Y40: 1 | Z40: 序号2箱装4万颗 | AD40: 0 | AE40: 0.02 | AF40: =_xlfn.DISPIMG("ID_533EC456924442BD9A4924A4E3684D7C",1) -> =DISPIMG("ID_533EC456924442BD9A4924A4E3684D7C",1) | AL40: 158.3 | AM40: 9323.87 | AO40: 40000 | AP40: PCE | AQ40: WHSU2789070 | AR40: 45660 | AS40: 030F500175 | AT40: 45674 | AU40: 45677 | AV40: 20FT | AW40: WAN HAI 371/S011
A41: 31 | B41: 7326909000 | C41: 732690 | D41: J00016-Ladle Set-大勺套装 | E41: 1.0t*9.7*117.9齿条 | F41: 1.0t x 9.7 x 117.9 rack | I41: KGM | J41: 76 | K41: 16000 | L41: PCE | P41: 139.42 | Q41: 10595.92 | T41: 88.94 | V41: 76 | X41: 序号3-4 | Y41: 5 | Z41: 序号3至4箱装8千颗 | AD41: 0 | AE41: 0.1 | AF41: =_xlfn.DISPIMG("ID_A095E048115E4230A5098DD4252295AF",1) -> =DISPIMG("ID_A095E048115E4230A5098DD4252295AF",1) | AL41: 139.42 | AM41: 10595.92 | AO41: 16000 | AP41: PCE | AQ41: WHSU2789070 | AR41: 45660 | AS41: 030F500175 | AT41: 45674 | AU41: 45677 | AV41: 20FT | AW41: WAN HAI 371/S011
A42: 32 | B42: 7326909000 | C42: 732690 | D42: J00015-Spade Set-铲子套装 | E42: 0.8t*7.2*71齿条 | F42: 0.8t*7.2*71 rack | I42: KGM | J42: 64.38 | K42: 37000 | L42: PCE | P42: 177.5 | Q42: 11427.45 | T42: 69.72 | V42: 64.38 | X42: 序号8-9 | Y42: 2 | Z42: 序号8箱装2.1万颗 序号9箱装1.6万颗 | AD42: 0 | AE42: 0.04 | AF42: =_xlfn.DISPIMG("ID_39FBA0FA05C84292AB6B4BEDE7A43250",1) -> =DISPIMG("ID_39FBA0FA05C84292AB6B4BEDE7A43250",1) | AL42: 177.5 | AM42: 11427.45 | AO42: 37000 | AP42: PCE | AQ42: WHSU2789070 | AR42: 45660 | AS42: 030F500175 | AT42: 45674 | AU42: 45677 | AV42: 20FT | AW42: WAN HAI 371/S011
...

Sheet 类别金额
A3: 序号 | B3: 类别 | C3: 金额
B4: 水口料 | C4: =SUMIFS('5.21出货明细'!AA:AA,'5.21出货明细'!I:I,B4) -> 0
B5: 色粉 | C5: =SUMIFS('5.21出货明细'!AA:AA,'5.21出货明细'!I:I,B5) -> 0
B6: 化学品 | C6: =SUMIFS('5.21出货明细'!AA:AA,'5.21出货明细'!I:I,B6) -> 0
B7: 原料 | C7: =SUMIFS('5.21出货明细'!AA:AA,'5.21出货明细'!I:I,B7) -> 0
B8: 电子类 | C8: =SUMIFS('5.21出货明细'!AA:AA,'5.21出货明细'!I:I,B8) -> 0
B9: 塑胶 | C9: =SUMIFS('5.21出货明细'!AA:AA,'5.21出货明细'!I:I,B9) -> 1411.8
B10: 搪胶 | C10: =SUMIFS('5.21出货明细'!AA:AA,'5.21出货明细'!I:I,B10) -> 0
B11: 五金 | C11: =SUMIFS('5.21出货明细'!AA:AA,'5.21出货明细'!I:I,B11) -> 0
B12: 电池 | C12: =SUMIFS('5.21出货明细'!AA:AA,'5.21出货明细'!I:I,B12) -> 0
B13: 吸塑 | C13: =SUMIFS('5.21出货明细'!AA:AA,'5.21出货明细'!I:I,B13) -> 0
B14: 胶袋 | C14: =SUMIFS('5.21出货明细'!AA:AA,'5.21出货明细'!I:I,B14) -> 0
B15: 利宝说明书 | C15: =SUMIFS('5.21出货明细'!AA:AA,'5.21出货明细'!I:I,B15) -> 0
... B25: 注塑模具 | C25: =SUMIFS('5.21出货明细'!AA:AA,'5.21出货明细'!I:I,B25) -> 0
B26: 签办
C27: =SUM(C4:C26) -> 1411.8

Sheet 实业合同
B1: 華登製品實業有限公司
B2: (ROYAL REGENT PRODUCTS INDUSTRIES LIMITED)
B3: 购销合同 Purchase Contract
B5: 买方: The Buyers: | C5: 華登製品實業有限公司 | G5: 合同编码： No.: | H5: RPIRRI260276
C6: ROYAL REGENT PRODUCTS INDUSTRIES LIMITED
C7: 九龍尖沙咀科学馆道1号康宏广场南座12楼07-08室
C8: Unit 07-08,12/F,Greenfield Tower,Concordia Plaza,No.1 Science Museum Road,Tsim Sha Tsui,Kowloon,Postal Code:999077,Hong Kong TEL: 00852-2425 0720 FAX: 00852-2424 3407 EMAIL: chloe@royalregenthk.com Attention: Ms Tang
G9: 签定日期： Date: | H9: 46076
B11: 卖方: The Sellers: | C11: 深圳市华胜益出口贸易有限公司
C12: SHENZHEN HUASHENGYI EXPORT TRADING LIMITED
C13: 深圳市龙华区大浪街道龙胜社区龙胜综合服务大楼602 Room 602, Longsheng Comprehensive Service Building, Longsheng Community, Dalang Street, Longhua District, Shenzhen City,Postal Code518083, China TEL: 0755-27745367 Email: liuyan@hanson2.com ATTN: Peng yuqiang | G13: 签定地点： Signed at: | H13: SHENZHEN
B15: The Consignee: | C15: PT. ROYAL REGENT INDONESIA
C16: KAWASAN INDUSTRI KENDAL, JL. WANAMARTA RAYA NO 33A & 35, BRANGSONG, BRANGSONG, KAB. KENDAL, JAWA TENGAH, 51371, INDONESIA
C17: Tel.: 62 895-3269-82429 Email: exim@royalregentid.com，exim2@royalregentid.com，exim3@royalregentid.com
C18: Attention: Novi Azka Tiurlan Putri Marpaung
B19: 经甲乙双方确认，根据下列条款订立本合同：
B20: The undersigned Sellers and Buyers have confirmed this contrasct in accordance with theterms and conditions stipulated below:
B22: 型 号 Item No. | C22: 品名描述 Names and Descriptions | D22: 數量 Quantities | E22: 單位 Unit | F22: 單價 Unit Price | G22: 金額 Amount | H22: 備註
F23: FOB IDSRG,Semarang
A24: 1 | B24: {=LOOKUP(1,0/(('5.21出货明细'!V:V=$H$5)*('5.21出货明细'!A:A=A24)),'5.21出货明细'!D:D)} -> #N/A | C24: {=LOOKUP(1,0/(('5.21出货明细'!V:V=$H$5)*('5.21出货明细'!A:A=A24)),'5.21出货明细'!G:G&'5.21出货明细'!F:F)} -> #N/A | D24: {=LOOKUP(1,0/(('5.21出货明细'!V:V=$H$5)*('5.21出货明细'!A:A=A24)),'5.21出货明细'!K:K)} -> #N/A | E24: {=LOOKUP(1,0/(('5.21出货明细'!V:V=$H$5)*('5.21出货明细'!A:A=A24)),'5.21出货明细'!J:J)} -> #N/A | F24: {=LOOKUP(1,0/(('5.21出货明细'!V:V=$H$5)*('5.21出货明细'!A:A=A24)),'5.21出货明细'!Z:Z)} -> #N/A | G24: =F24*D24 -> #N/A
A25: 2 | B25: {=LOOKUP(1,0/(('5.21出货明细'!V:V=$H$5)*('5.21出货明细'!A:A=A25)),'5.21出货明细'!D:D)} -> #N/A | C25: {=LOOKUP(1,0/(('5.21出货明细'!V:V=$H$5)*('5.21出货明细'!A:A=A25)),'5.21出货明细'!G:G&'5.21出货明细'!F:F)} -> #N/A | D25: {=LOOKUP(1,0/(('5.21出货明细'!V:V=$H$5)*('5.21出货明细'!A:A=A25)),'5.21出货明细'!K:K)} -> #N/A | E25: {=LOOKUP(1,0/(('5.21出货明细'!V:V=$H$5)*('5.21出货明细'!A:A=A25)),'5.21出货明细'!J:J)} -> #N/A | F25: {=LOOKUP(1,0/(('5.21出货明细'!V:V=$H$5)*('5.21出货明细'!A:A=A25)),'5.21出货明细'!Z:Z)} -> #N/A | G25: =F25*D25 -> #N/A
A26: 3 | B26: {=LOOKUP(1,0/(('5.21出货明细'!V:V=$H$5)*('5.21出货明细'!A:A=A26)),'5.21出货明细'!D:D)} -> #N/A | C26: {=LOOKUP(1,0/(('5.21出货明细'!V:V=$H$5)*('5.21出货明细'!A:A=A26)),'5.21出货明细'!G:G&'5.21出货明细'!F:F)} -> #N/A | D26: {=LOOKUP(1,0/(('5.21出货明细'!V:V=$H$5)*('5.21出货明细'!A:A=A26)),'5.21出货明细'!K:K)} -> #N/A | E26: {=LOOKUP(1,0/(('5.21出货明细'!V:V=$H$5)*('5.21出货明细'!A:A=A26)),'5.21出货明细'!J:J)} -> #N/A | F26: {=LOOKUP(1,0/(('5.21出货明细'!V:V=$H$5)*('5.21出货明细'!A:A=A26)),'5.21出货明细'!Z:Z)} -> #N/A | G26: =F26*D26 -> #N/A
A27: 4 | B27: {=LOOKUP(1,0/(('5.21出货明细'!V:V=$H$5)*('5.21出货明细'!A:A=A27)),'5.21出货明细'!D:D)} -> #N/A | C27: {=LOOKUP(1,0/(('5.21出货明细'!V:V=$H$5)*('5.21出货明细'!A:A=A27)),'5.21出货明细'!G:G&'5.21出货明细'!F:F)} -> #N/A | D27: {=LOOKUP(1,0/(('5.21出货明细'!V:V=$H$5)*('5.21出货明细'!A:A=A27)),'5.21出货明细'!K:K)} -> #N/A | E27: {=LOOKUP(1,0/(('5.21出货明细'!V:V=$H$5)*('5.21出货明细'!A:A=A27)),'5.21出货明细'!J:J)} -> #N/A | F27: {=LOOKUP(1,0/(('5.21出货明细'!V:V=$H$5)*('5.21出货明细'!A:A=A27)),'5.21出货明细'!Z:Z)} -> #N/A | G27: =F27*D27 -> #N/A
A28: 5 | B28: {=LOOKUP(1,0/(('5.21出货明细'!V:V=$H$5)*('5.21出货明细'!A:A=A28)),'5.21出货明细'!D:D)} -> #N/A | C28: {=LOOKUP(1,0/(('5.21出货明细'!V:V=$H$5)*('5.21出货明细'!A:A=A28)),'5.21出货明细'!G:G&'5.21出货明细'!F:F)} -> #N/A | D28: {=LOOKUP(1,0/(('5.21出货明细'!V:V=$H$5)*('5.21出货明细'!A:A=A28)),'5.21出货明细'!K:K)} -> #N/A | E28: {=LOOKUP(1,0/(('5.21出货明细'!V:V=$H$5)*('5.21出货明细'!A:A=A28)),'5.21出货明细'!J:J)} -> #N/A | F28: {=LOOKUP(1,0/(('5.21出货明细'!V:V=$H$5)*('5.21出货明细'!A:A=A28)),'5.21出货明细'!Z:Z)} -> #N/A | G28: =F28*D28 -> #N/A
A29: 6 | B29: {=LOOKUP(1,0/(('5.21出货明细'!V:V=$H$5)*('5.21出货明细'!A:A=A29)),'5.21出货明细'!D:D)} -> #N/A | C29: {=LOOKUP(1,0/(('5.21出货明细'!V:V=$H$5)*('5.21出货明细'!A:A=A29)),'5.21出货明细'!G:G&'5.21出货明细'!F:F)} -> #N/A | D29: {=LOOKUP(1,0/(('5.21出货明细'!V:V=$H$5)*('5.21出货明细'!A:A=A29)),'5.21出货明细'!K:K)} -> #N/A | E29: {=LOOKUP(1,0/(('5.21出货明细'!V:V=$H$5)*('5.21出货明细'!A:A=A29)),'5.21出货明细'!J:J)} -> #N/A | F29: {=LOOKUP(1,0/(('5.21出货明细'!V:V=$H$5)*('5.21出货明细'!A:A=A29)),'5.21出货明细'!Z:Z)} -> #N/A | G29: =F29*D29 -> #N/A
A30: 7 | B30: {=LOOKUP(1,0/(('5.21出货明细'!V:V=$H$5)*('5.21出货明细'!A:A=A30)),'5.21出货明细'!D:D)} -> #N/A | C30: {=LOOKUP(1,0/(('5.21出货明细'!V:V=$H$5)*('5.21出货明细'!A:A=A30)),'5.21出货明细'!G:G&'5.21出货明细'!F:F)} -> #N/A | D30: {=LOOKUP(1,0/(('5.21出货明细'!V:V=$H$5)*('5.21出货明细'!A:A=A30)),'5.21出货明细'!K:K)} -> #N/A | E30: {=LOOKUP(1,0/(('5.21出货明细'!V:V=$H$5)*('5.21出货明细'!A:A=A30)),'5.21出货明细'!J:J)} -> #N/A | F30: {=LOOKUP(1,0/(('5.21出货明细'!V:V=$H$5)*('5.21出货明细'!A:A=A30)),'5.21出货明细'!Z:Z)} -> #N/A | G30: =F30*D30 -> #N/A
A31: 8 | B31: {=LOOKUP(1,0/(('5.21出货明细'!V:V=$H$5)*('5.21出货明细'!A:A=A31)),'5.21出货明细'!D:D)} -> #N/A | C31: {=LOOKUP(1,0/(('5.21出货明细'!V:V=$H$5)*('5.21出货明细'!A:A=A31)),'5.21出货明细'!G:G&'5.21出货明细'!F:F)} -> #N/A | D31: {=LOOKUP(1,0/(('5.21出货明细'!V:V=$H$5)*('5.21出货明细'!A:A=A31)),'5.21出货明细'!K:K)} -> #N/A | E31: {=LOOKUP(1,0/(('5.21出货明细'!V:V=$H$5)*('5.21出货明细'!A:A=A31)),'5.21出货明细'!J:J)} -> #N/A | F31: {=LOOKUP(1,0/(('5.21出货明细'!V:V=$H$5)*('5.21出货明细'!A:A=A31)),'5.21出货明细'!Z:Z)} -> #N/A | G31: =F31*D31 -> #N/A
A32: 9 | B32: {=LOOKUP(1,0/(('5.21出货明细'!V:V=$H$5)*('5.21出货明细'!A:A=A32)),'5.21出货明细'!D:D)} -> #N/A | C32: {=LOOKUP(1,0/(('5.21出货明细'!V:V=$H$5)*('5.21出货明细'!A:A=A32)),'5.21出货明细'!G:G&'5.21出货明细'!F:F)} -> #N/A | D32: {=LOOKUP(1,0/(('5.21出货明细'!V:V=$H$5)*('5.21出货明细'!A:A=A32)),'5.21出货明细'!K:K)} -> #N/A | E32: {=LOOKUP(1,0/(('5.21出货明细'!V:V=$H$5)*('5.21出货明细'!A:A=A32)),'5.21出货明细'!J:J)} -> #N/A | F32: {=LOOKUP(1,0/(('5.21出货明细'!V:V=$H$5)*('5.21出货明细'!A:A=A32)),'5.21出货明细'!Z:Z)} -> #N/A | G32: =F32*D32 -> #N/A
A33: 10 | B33: {=LOOKUP(1,0/(('5.21出货明细'!V:V=$H$5)*('5.21出货明细'!A:A=A33)),'5.21出货明细'!D:D)} -> #N/A | C33: {=LOOKUP(1,0/(('5.21出货明细'!V:V=$H$5)*('5.21出货明细'!A:A=A33)),'5.21出货明细'!G:G&'5.21出货明细'!F:F)} -> #N/A | D33: {=LOOKUP(1,0/(('5.21出货明细'!V:V=$H$5)*('5.21出货明细'!A:A=A33)),'5.21出货明细'!K:K)} -> #N/A | E33: {=LOOKUP(1,0/(('5.21出货明细'!V:V=$H$5)*('5.21出货明细'!A:A=A33)),'5.21出货明细'!J:J)} -> #N/A | F33: {=LOOKUP(1,0/(('5.21出货明细'!V:V=$H$5)*('5.21出货明细'!A:A=A33)),'5.21出货明细'!Z:Z)} -> #N/A | G33: =F33*D33 -> #N/A
A34: 11 | B34: {=LOOKUP(1,0/(('5.21出货明细'!V:V=$H$5)*('5.21出货明细'!A:A=A34)),'5.21出货明细'!D:D)} -> #N/A | C34: {=LOOKUP(1,0/(('5.21出货明细'!V:V=$H$5)*('5.21出货明细'!A:A=A34)),'5.21出货明细'!G:G&'5.21出货明细'!F:F)} -> #N/A | D34: {=LOOKUP(1,0/(('5.21出货明细'!V:V=$H$5)*('5.21出货明细'!A:A=A34)),'5.21出货明细'!K:K)} -> #N/A | E34: {=LOOKUP(1,0/(('5.21出货明细'!V:V=$H$5)*('5.21出货明细'!A:A=A34)),'5.21出货明细'!J:J)} -> #N/A | F34: {=LOOKUP(1,0/(('5.21出货明细'!V:V=$H$5)*('5.21出货明细'!A:A=A34)),'5.21出货明细'!Z:Z)} -> #N/A | G34: =F34*D34 -> #N/A
A35: 12 | B35: {=LOOKUP(1,0/(('5.21出货明细'!V:V=$H$5)*('5.21出货明细'!A:A=A35)),'5.21出货明细'!D:D)} -> #N/A | C35: {=LOOKUP(1,0/(('5.21出货明细'!V:V=$H$5)*('5.21出货明细'!A:A=A35)),'5.21出货明细'!G:G&'5.21出货明细'!F:F)} -> #N/A | D35: {=LOOKUP(1,0/(('5.21出货明细'!V:V=$H$5)*('5.21出货明细'!A:A=A35)),'5.21出货明细'!K:K)} -> #N/A | E35: {=LOOKUP(1,0/(('5.21出货明细'!V:V=$H$5)*('5.21出货明细'!A:A=A35)),'5.21出货明细'!J:J)} -> #N/A | F35: {=LOOKUP(1,0/(('5.21出货明细'!V:V=$H$5)*('5.21出货明细'!A:A=A35)),'5.21出货明细'!Z:Z)} -> #N/A | G35: =F35*D35 -> #N/A
... A41: 18 | B41: {=LOOKUP(1,0/(('5.21出货明细'!V:V=$H$5)*('5.21出货明细'!A:A=A41)),'5.21出货明细'!D:D)} -> #N/A | C41: {=LOOKUP(1,0/(('5.21出货明细'!V:V=$H$5)*('5.21出货明细'!A:A=A41)),'5.21出货明细'!G:G&'5.21出货明细'!F:F)} -> #N/A | D41: {=LOOKUP(1,0/(('5.21出货明细'!V:V=$H$5)*('5.21出货明细'!A:A=A41)),'5.21出货明细'!K:K)} -> #N/A | E41: {=LOOKUP(1,0/(('5.21出货明细'!V:V=$H$5)*('5.21出货明细'!A:A=A41)),'5.21出货明细'!J:J)} -> #N/A | F41: {=LOOKUP(1,0/(('5.21出货明细'!V:V=$H$5)*('5.21出货明细'!A:A=A41)),'5.21出货明细'!Z:Z)} -> #N/A | G41: =F41*D41 -> #N/A
G42: =SUM(G24:G41) -> #N/A
B44: 交貨日期: | C44: BEFORE April.24,2026
B45: 1.成交价格术语：Terms: | C45: FOB IDSRG,Semarang
B46: 2.运输起讫： | C46: FROM SHENZHEN,CHINA TO ID (从中国深圳到印尼)
B47: 3.装运期： Shipment date: | C47: BEFORE May.1,2026 | E47: 运输方式： Transport: | G47: BY SEA
B48: 4.付款条件： Terms of payment: | C48: T/T
B49: 5.本合同共 2 份，自双方代表签字（盖章）之日生效。
B50: This contract is in TWO copies, effective since being signed / sealed by both parties.
...

Sheet 实业发票
B1: 華登製品實業有限公司
B2: ROYAL REGENT PRODUCTS INDUSTRIES LIMITED
B3: Unit 07-08,12/F,Greenfield Tower,Concordia Plaza,No.1 Science Museum Road,Tsim Sha Tsui,Kowloon,Postal Code:999077,Hong Kong
B4: TEL: 00852-2425 0720 FAX: 00852-2424 3407 EMAIL: chloe@royalregenthk.com
B5: 商 业 发 票
B6: COMMERCIAL INVOICE
B8: 买方:
B9: The Buyers: M/S. | G9: 号码 No. | H9: PR202600276
B10: 華登製品實業有限公司
B11: Unit 07-08,12/F,Greenfield Tower,Concordia Plaza,No.1 Science Museum Road,Tsim Sha Tsui,Kowloon,Postal Code:999077,Hong Kong TEL: 00852-2425 0720 FAX: 00852-2424 3407 EMAIL: chloe@royalregenthk.com Attention: Ms Tang | G11: 日期 Date | H11: =实业合同!H9 -> 46076
B13: Consignee：M/S. | G13: 合同号 Contract No. | H13: =实业合同!H5 -> RPIRRI260276
B14: PT. ROYAL REGENT INDONESIA
B15: Tax ID: 61.146.021.3-513.000 KAWASAN INDUSTRI KENDAL, JL. WANAMARTA RAYA NO 33A & 35, BRANGSONG, BRANGSONG, KAB. KENDAL, JAWA TENGAH, 51371, INDONESIA
G16: 运输方式： | H16: BY SEA
B17: Tel.: 62 895-3269-82429 Email: exim@royalregentid.com，exim2@royalregentid.com，exim3@royalregentid.com
B18: Attention: Novi Azka Tiurlan Putri Marpaung
B19: 卖方:
B20: The Sellers: M/S.
B21: 深圳市华胜益出口贸易有限公司
B22: SHENZHEN HUASHENGYI EXPORT TRADING LIMITED
B23: 深圳市龙华区大浪街道龙胜社区龙胜综合服务大楼602 Room 602, Longsheng Comprehensive Service Building, Longsheng Community, Dalang Street, Longhua District, Shenzhen City,Postal Code518083, China TEL: 0755-27745367 Email: liuyan@hanson2.com ATTN: Peng yuqiang
B27: 装运口岸 From： | C27: SHENZHEN,CHINA(中国深圳) | F27: 目的地 To： | G27: Indonesia(印度尼西亚)
B28: 型 号 Item No. | C28: 品名描述 Names and Descriptions | D28: 单位 Unit | E28: HS Code | F28: 数 量 Quantities | G28: 单 价 Unit Price | H28: 总 值 Amount
G29: FOB IDSRG,Semarang
A30: 1 | B30: {=LOOKUP(1,0/(('5.21出货明细'!V:V=$H$13)*('5.21出货明细'!X:X=$H$9)*('5.21出货明细'!A:A=A30)),'5.21出货明细'!D:D)} -> #N/A | C30: {=LOOKUP(1,0/(('5.21出货明细'!V:V=$H$13)*('5.21出货明细'!X:X=$H$9)*('5.21出货明细'!A:A=A30)),'5.21出货明细'!G:G&'5.21出货明细'!F:F)} -> #N/A | D30: {=LOOKUP(1,0/(('5.21出货明细'!D:D=B30)*('5.21出货明细'!G:G&'5.21出货明细'!F:F=C30)),'5.21出货明细'!J:J)} -> #N/A | E30: {=LOOKUP(1,0/(('5.21出货明细'!D:D=B30)*('5.21出货明细'!G:G&'5.21出货明细'!F:F=C30)),'5.21出货明细'!C:C)} -> #N/A | F30: {=LOOKUP(1,0/(('5.21出货明细'!D:D=B30)*('5.21出货明细'!G:G&'5.21出货明细'!F:F=C30)),'5.21出货明细'!K:K)} -> #N/A | G30: {=LOOKUP(1,0/(('5.21出货明细'!D:D=B30)*('5.21出货明细'!G:G&'5.21出货明细'!F:F=C30)),'5.21出货明细'!Z:Z)} -> #N/A | H30: =G30*F30 -> #N/A
A31: 2 | B31: {=LOOKUP(1,0/(('5.21出货明细'!V:V=$H$13)*('5.21出货明细'!X:X=$H$9)*('5.21出货明细'!A:A=A31)),'5.21出货明细'!D:D)} -> #N/A | C31: {=LOOKUP(1,0/(('5.21出货明细'!V:V=$H$13)*('5.21出货明细'!X:X=$H$9)*('5.21出货明细'!A:A=A31)),'5.21出货明细'!G:G&'5.21出货明细'!F:F)} -> #N/A | D31: {=LOOKUP(1,0/(('5.21出货明细'!D:D=B31)*('5.21出货明细'!G:G&'5.21出货明细'!F:F=C31)),'5.21出货明细'!J:J)} -> #N/A | E31: {=LOOKUP(1,0/(('5.21出货明细'!D:D=B31)*('5.21出货明细'!G:G&'5.21出货明细'!F:F=C31)),'5.21出货明细'!C:C)} -> #N/A | F31: {=LOOKUP(1,0/(('5.21出货明细'!D:D=B31)*('5.21出货明细'!G:G&'5.21出货明细'!F:F=C31)),'5.21出货明细'!K:K)} -> #N/A | G31: {=LOOKUP(1,0/(('5.21出货明细'!D:D=B31)*('5.21出货明细'!G:G&'5.21出货明细'!F:F=C31)),'5.21出货明细'!Z:Z)} -> #N/A | H31: =G31*F31 -> #N/A
A32: 3 | B32: {=LOOKUP(1,0/(('5.21出货明细'!V:V=$H$13)*('5.21出货明细'!X:X=$H$9)*('5.21出货明细'!A:A=A32)),'5.21出货明细'!D:D)} -> #N/A | C32: {=LOOKUP(1,0/(('5.21出货明细'!V:V=$H$13)*('5.21出货明细'!X:X=$H$9)*('5.21出货明细'!A:A=A32)),'5.21出货明细'!G:G&'5.21出货明细'!F:F)} -> #N/A | D32: {=LOOKUP(1,0/(('5.21出货明细'!D:D=B32)*('5.21出货明细'!G:G&'5.21出货明细'!F:F=C32)),'5.21出货明细'!J:J)} -> #N/A | E32: {=LOOKUP(1,0/(('5.21出货明细'!D:D=B32)*('5.21出货明细'!G:G&'5.21出货明细'!F:F=C32)),'5.21出货明细'!C:C)} -> #N/A | F32: {=LOOKUP(1,0/(('5.21出货明细'!D:D=B32)*('5.21出货明细'!G:G&'5.21出货明细'!F:F=C32)),'5.21出货明细'!K:K)} -> #N/A | G32: {=LOOKUP(1,0/(('5.21出货明细'!D:D=B32)*('5.21出货明细'!G:G&'5.21出货明细'!F:F=C32)),'5.21出货明细'!Z:Z)} -> #N/A | H32: =G32*F32 -> #N/A
A33: 4 | B33: {=LOOKUP(1,0/(('5.21出货明细'!V:V=$H$13)*('5.21出货明细'!X:X=$H$9)*('5.21出货明细'!A:A=A33)),'5.21出货明细'!D:D)} -> #N/A | C33: {=LOOKUP(1,0/(('5.21出货明细'!V:V=$H$13)*('5.21出货明细'!X:X=$H$9)*('5.21出货明细'!A:A=A33)),'5.21出货明细'!G:G&'5.21出货明细'!F:F)} -> #N/A | D33: {=LOOKUP(1,0/(('5.21出货明细'!D:D=B33)*('5.21出货明细'!G:G&'5.21出货明细'!F:F=C33)),'5.21出货明细'!J:J)} -> #N/A | E33: {=LOOKUP(1,0/(('5.21出货明细'!D:D=B33)*('5.21出货明细'!G:G&'5.21出货明细'!F:F=C33)),'5.21出货明细'!C:C)} -> #N/A | F33: {=LOOKUP(1,0/(('5.21出货明细'!D:D=B33)*('5.21出货明细'!G:G&'5.21出货明细'!F:F=C33)),'5.21出货明细'!K:K)} -> #N/A | G33: {=LOOKUP(1,0/(('5.21出货明细'!D:D=B33)*('5.21出货明细'!G:G&'5.21出货明细'!F:F=C33)),'5.21出货明细'!Z:Z)} -> #N/A | H33: =G33*F33 -> #N/A
A34: 5 | B34: {=LOOKUP(1,0/(('5.21出货明细'!V:V=$H$13)*('5.21出货明细'!X:X=$H$9)*('5.21出货明细'!A:A=A34)),'5.21出货明细'!D:D)} -> #N/A | C34: {=LOOKUP(1,0/(('5.21出货明细'!V:V=$H$13)*('5.21出货明细'!X:X=$H$9)*('5.21出货明细'!A:A=A34)),'5.21出货明细'!G:G&'5.21出货明细'!F:F)} -> #N/A | D34: {=LOOKUP(1,0/(('5.21出货明细'!D:D=B34)*('5.21出货明细'!G:G&'5.21出货明细'!F:F=C34)),'5.21出货明细'!J:J)} -> #N/A | E34: {=LOOKUP(1,0/(('5.21出货明细'!D:D=B34)*('5.21出货明细'!G:G&'5.21出货明细'!F:F=C34)),'5.21出货明细'!C:C)} -> #N/A | F34: {=LOOKUP(1,0/(('5.21出货明细'!D:D=B34)*('5.21出货明细'!G:G&'5.21出货明细'!F:F=C34)),'5.21出货明细'!K:K)} -> #N/A | G34: {=LOOKUP(1,0/(('5.21出货明细'!D:D=B34)*('5.21出货明细'!G:G&'5.21出货明细'!F:F=C34)),'5.21出货明细'!Z:Z)} -> #N/A | H34: =G34*F34 -> #N/A
A35: 6 | B35: {=LOOKUP(1,0/(('5.21出货明细'!V:V=$H$13)*('5.21出货明细'!X:X=$H$9)*('5.21出货明细'!A:A=A35)),'5.21出货明细'!D:D)} -> #N/A | C35: {=LOOKUP(1,0/(('5.21出货明细'!V:V=$H$13)*('5.21出货明细'!X:X=$H$9)*('5.21出货明细'!A:A=A35)),'5.21出货明细'!G:G&'5.21出货明细'!F:F)} -> #N/A | D35: {=LOOKUP(1,0/(('5.21出货明细'!D:D=B35)*('5.21出货明细'!G:G&'5.21出货明细'!F:F=C35)),'5.21出货明细'!J:J)} -> #N/A | E35: {=LOOKUP(1,0/(('5.21出货明细'!D:D=B35)*('5.21出货明细'!G:G&'5.21出货明细'!F:F=C35)),'5.21出货明细'!C:C)} -> #N/A | F35: {=LOOKUP(1,0/(('5.21出货明细'!D:D=B35)*('5.21出货明细'!G:G&'5.21出货明细'!F:F=C35)),'5.21出货明细'!K:K)} -> #N/A | G35: {=LOOKUP(1,0/(('5.21出货明细'!D:D=B35)*('5.21出货明细'!G:G&'5.21出货明细'!F:F=C35)),'5.21出货明细'!Z:Z)} -> #N/A | H35: =G35*F35 -> #N/A
A36: 7 | B36: {=LOOKUP(1,0/(('5.21出货明细'!V:V=$H$13)*('5.21出货明细'!X:X=$H$9)*('5.21出货明细'!A:A=A36)),'5.21出货明细'!D:D)} -> #N/A | C36: {=LOOKUP(1,0/(('5.21出货明细'!V:V=$H$13)*('5.21出货明细'!X:X=$H$9)*('5.21出货明细'!A:A=A36)),'5.21出货明细'!G:G&'5.21出货明细'!F:F)} -> #N/A | D36: {=LOOKUP(1,0/(('5.21出货明细'!D:D=B36)*('5.21出货明细'!G:G&'5.21出货明细'!F:F=C36)),'5.21出货明细'!J:J)} -> #N/A | E36: {=LOOKUP(1,0/(('5.21出货明细'!D:D=B36)*('5.21出货明细'!G:G&'5.21出货明细'!F:F=C36)),'5.21出货明细'!C:C)} -> #N/A | F36: {=LOOKUP(1,0/(('5.21出货明细'!D:D=B36)*('5.21出货明细'!G:G&'5.21出货明细'!F:F=C36)),'5.21出货明细'!K:K)} -> #N/A | G36: {=LOOKUP(1,0/(('5.21出货明细'!D:D=B36)*('5.21出货明细'!G:G&'5.21出货明细'!F:F=C36)),'5.21出货明细'!Z:Z)} -> #N/A | H36: =G36*F36 -> #N/A
A37: 8 | B37: {=LOOKUP(1,0/(('5.21出货明细'!V:V=$H$13)*('5.21出货明细'!X:X=$H$9)*('5.21出货明细'!A:A=A37)),'5.21出货明细'!D:D)} -> #N/A | C37: {=LOOKUP(1,0/(('5.21出货明细'!V:V=$H$13)*('5.21出货明细'!X:X=$H$9)*('5.21出货明细'!A:A=A37)),'5.21出货明细'!G:G&'5.21出货明细'!F:F)} -> #N/A | D37: {=LOOKUP(1,0/(('5.21出货明细'!D:D=B37)*('5.21出货明细'!G:G&'5.21出货明细'!F:F=C37)),'5.21出货明细'!J:J)} -> #N/A | E37: {=LOOKUP(1,0/(('5.21出货明细'!D:D=B37)*('5.21出货明细'!G:G&'5.21出货明细'!F:F=C37)),'5.21出货明细'!C:C)} -> #N/A | F37: {=LOOKUP(1,0/(('5.21出货明细'!D:D=B37)*('5.21出货明细'!G:G&'5.21出货明细'!F:F=C37)),'5.21出货明细'!K:K)} -> #N/A | G37: {=LOOKUP(1,0/(('5.21出货明细'!D:D=B37)*('5.21出货明细'!G:G&'5.21出货明细'!F:F=C37)),'5.21出货明细'!Z:Z)} -> #N/A | H37: =G37*F37 -> #N/A
A38: 9 | B38: {=LOOKUP(1,0/(('5.21出货明细'!V:V=$H$13)*('5.21出货明细'!X:X=$H$9)*('5.21出货明细'!A:A=A38)),'5.21出货明细'!D:D)} -> #N/A | C38: {=LOOKUP(1,0/(('5.21出货明细'!V:V=$H$13)*('5.21出货明细'!X:X=$H$9)*('5.21出货明细'!A:A=A38)),'5.21出货明细'!G:G&'5.21出货明细'!F:F)} -> #N/A | D38: {=LOOKUP(1,0/(('5.21出货明细'!D:D=B38)*('5.21出货明细'!G:G&'5.21出货明细'!F:F=C38)),'5.21出货明细'!J:J)} -> #N/A | E38: {=LOOKUP(1,0/(('5.21出货明细'!D:D=B38)*('5.21出货明细'!G:G&'5.21出货明细'!F:F=C38)),'5.21出货明细'!C:C)} -> #N/A | F38: {=LOOKUP(1,0/(('5.21出货明细'!D:D=B38)*('5.21出货明细'!G:G&'5.21出货明细'!F:F=C38)),'5.21出货明细'!K:K)} -> #N/A | G38: {=LOOKUP(1,0/(('5.21出货明细'!D:D=B38)*('5.21出货明细'!G:G&'5.21出货明细'!F:F=C38)),'5.21出货明细'!Z:Z)} -> #N/A | H38: =G38*F38 -> #N/A
A39: 10 | B39: {=LOOKUP(1,0/(('5.21出货明细'!V:V=$H$13)*('5.21出货明细'!X:X=$H$9)*('5.21出货明细'!A:A=A39)),'5.21出货明细'!D:D)} -> #N/A | C39: {=LOOKUP(1,0/(('5.21出货明细'!V:V=$H$13)*('5.21出货明细'!X:X=$H$9)*('5.21出货明细'!A:A=A39)),'5.21出货明细'!G:G&'5.21出货明细'!F:F)} -> #N/A | D39: {=LOOKUP(1,0/(('5.21出货明细'!D:D=B39)*('5.21出货明细'!G:G&'5.21出货明细'!F:F=C39)),'5.21出货明细'!J:J)} -> #N/A | E39: {=LOOKUP(1,0/(('5.21出货明细'!D:D=B39)*('5.21出货明细'!G:G&'5.21出货明细'!F:F=C39)),'5.21出货明细'!C:C)} -> #N/A | F39: {=LOOKUP(1,0/(('5.21出货明细'!D:D=B39)*('5.21出货明细'!G:G&'5.21出货明细'!F:F=C39)),'5.21出货明细'!K:K)} -> #N/A | G39: {=LOOKUP(1,0/(('5.21出货明细'!D:D=B39)*('5.21出货明细'!G:G&'5.21出货明细'!F:F=C39)),'5.21出货明细'!Z:Z)} -> #N/A | H39: =G39*F39 -> #N/A
A40: 11 | B40: {=LOOKUP(1,0/(('5.21出货明细'!V:V=$H$13)*('5.21出货明细'!X:X=$H$9)*('5.21出货明细'!A:A=A40)),'5.21出货明细'!D:D)} -> #N/A | C40: {=LOOKUP(1,0/(('5.21出货明细'!V:V=$H$13)*('5.21出货明细'!X:X=$H$9)*('5.21出货明细'!A:A=A40)),'5.21出货明细'!G:G&'5.21出货明细'!F:F)} -> #N/A | D40: {=LOOKUP(1,0/(('5.21出货明细'!D:D=B40)*('5.21出货明细'!G:G&'5.21出货明细'!F:F=C40)),'5.21出货明细'!J:J)} -> #N/A | E40: {=LOOKUP(1,0/(('5.21出货明细'!D:D=B40)*('5.21出货明细'!G:G&'5.21出货明细'!F:F=C40)),'5.21出货明细'!C:C)} -> #N/A | F40: {=LOOKUP(1,0/(('5.21出货明细'!D:D=B40)*('5.21出货明细'!G:G&'5.21出货明细'!F:F=C40)),'5.21出货明细'!K:K)} -> #N/A | G40: {=LOOKUP(1,0/(('5.21出货明细'!D:D=B40)*('5.21出货明细'!G:G&'5.21出货明细'!F:F=C40)),'5.21出货明细'!Z:Z)} -> #N/A | H40: =G40*F40 -> #N/A
A41: 12 | B41: {=LOOKUP(1,0/(('5.21出货明细'!V:V=$H$13)*('5.21出货明细'!X:X=$H$9)*('5.21出货明细'!A:A=A41)),'5.21出货明细'!D:D)} -> #N/A | C41: {=LOOKUP(1,0/(('5.21出货明细'!V:V=$H$13)*('5.21出货明细'!X:X=$H$9)*('5.21出货明细'!A:A=A41)),'5.21出货明细'!G:G&'5.21出货明细'!F:F)} -> #N/A | D41: {=LOOKUP(1,0/(('5.21出货明细'!D:D=B41)*('5.21出货明细'!G:G&'5.21出货明细'!F:F=C41)),'5.21出货明细'!J:J)} -> #N/A | E41: {=LOOKUP(1,0/(('5.21出货明细'!D:D=B41)*('5.21出货明细'!G:G&'5.21出货明细'!F:F=C41)),'5.21出货明细'!C:C)} -> #N/A | F41: {=LOOKUP(1,0/(('5.21出货明细'!D:D=B41)*('5.21出货明细'!G:G&'5.21出货明细'!F:F=C41)),'5.21出货明细'!K:K)} -> #N/A | G41: {=LOOKUP(1,0/(('5.21出货明细'!D:D=B41)*('5.21出货明细'!G:G&'5.21出货明细'!F:F=C41)),'5.21出货明细'!Z:Z)} -> #N/A | H41: =G41*F41 -> #N/A
... A47: 18 | B47: {=LOOKUP(1,0/(('5.21出货明细'!V:V=$H$13)*('5.21出货明细'!X:X=$H$9)*('5.21出货明细'!A:A=A47)),'5.21出货明细'!D:D)} -> #N/A | C47: {=LOOKUP(1,0/(('5.21出货明细'!V:V=$H$13)*('5.21出货明细'!X:X=$H$9)*('5.21出货明细'!A:A=A47)),'5.21出货明细'!G:G&'5.21出货明细'!F:F)} -> #N/A | D47: {=LOOKUP(1,0/(('5.21出货明细'!D:D=B47)*('5.21出货明细'!G:G&'5.21出货明细'!F:F=C47)),'5.21出货明细'!J:J)} -> #N/A | E47: {=LOOKUP(1,0/(('5.21出货明细'!D:D=B47)*('5.21出货明细'!G:G&'5.21出货明细'!F:F=C47)),'5.21出货明细'!C:C)} -> #N/A | F47: {=LOOKUP(1,0/(('5.21出货明细'!D:D=B47)*('5.21出货明细'!G:G&'5.21出货明细'!F:F=C47)),'5.21出货明细'!K:K)} -> #N/A | G47: {=LOOKUP(1,0/(('5.21出货明细'!D:D=B47)*('5.21出货明细'!G:G&'5.21出货明细'!F:F=C47)),'5.21出货明细'!Z:Z)} -> #N/A | H47: =G47*F47 -> #N/A
F48: TOTAL: | G48: =SUM(H30:H47) -> #N/A
B49: 总值大写 Total Amount: | C49: =G48 -> #N/A
B50: Beneficiary name :Shenzhen Huashengyi Export Trading Limited Account number : 15668277360001(USD) 15353466270052 (RMB) 15602776290037 (HKD) Beneficiary Bank: Ping An Bank Co., Ltd Swift code : SZDBCNBSXXX | F50: Beneficiary：SHENZHEN HUASHENGYI EXPORT TRADING LIMITED
...

Sheet 装箱单
A1: ROYAL REGENT PRODUCTS INDUSTRIES LIMITED
A2: Unit 07-08,12/F,Greenfield Tower,Concordia Plaza,No.1 Science Museum Road,Tsim Sha Tsui,Kowloon,Postal Code:999077,Hong Kong
A6: PACKING LIST
A8: 1 .Shipper: | D8: 2. Packing List Number | H8: 3. Page
A9: ROYAL REGENT PRODUCTS INDUSTRIES LIMITED Unit 07-08,12/F,Greenfield Tower,Concordia Plaza,No.1 Science Museum Road,Tsim Sha Tsui,Kowloon,Postal Code:999077,Hong Kong | D9: =实业发票!H9 -> PR202600276
D10: 4. Packing List Date
D11: 46134
A12: TEL: 00852-2425 0720 FAX: 00852-2424 3407 | D12: 5.PO# | H12: 6. OF#
A13: EMAIL: chloe@royalregenthk.com | D13: =实业合同!H5 -> RPIRRI260276
A14: Attention: Ms Tang
A15: 7. Consignee:
A16: PT. ROYAL REGENT INDONESIA | D16: 8. Container | H16: 9. Seal Number
A17: Tax ID: 61.146.021.3-513.000 | D17: BMOU6019197 | H17: EMCRZS9184
A18: KAWASAN INDUSTRI KENDAL, JL. WANAMARTA RAYA NO. 33A & 35,
A19: BRANGSONG, BRANGSONG, KAB. KENDAL, JAWA TENGAH, 51371,
A20: INDONESIA
A21: Tel.: 62 895-3269-82429
A22: Attention: Novi Azka Tiurlan Putri Marpaung
A23: Email: exim@royalregentid.com，exim2@royalregentid.com，exim3@royalregentid.com
A24: 序号 serial number | B24: 型 号 Item No. | C24: 品名描述 Names and Descriptions | D24: 数 量 Quantities | E24: 单位 Unit | F24: 数 量 Quantities | G24: 单位 Unit | H24: 毛重 Gross Weight Kgs | I24: 净重 Net Weight Kgs | J24: 箱数 Carton No. | K24: 立方数 CBM
A25: 1 | B25: {=LOOKUP(1,0/(('5.21出货明细'!X:X=$D$9)*('5.21出货明细'!A:A=A25)),'5.21出货明细'!D:D)} -> #N/A | C25: {=LOOKUP(1,0/(('5.21出货明细'!X:X=$D$9)*('5.21出货明细'!A:A=A25)),'5.21出货明细'!G:G&'5.21出货明细'!F:F)} -> #N/A | D25: {=LOOKUP(1,0/(('5.21出货明细'!X:X=$D$9)*('5.21出货明细'!A:A=A25)),'5.21出货明细'!K:K)} -> #N/A | E25: {=LOOKUP(1,0/(('5.21出货明细'!X:X=$D$9)*('5.21出货明细'!A:A=A25)),'5.21出货明细'!J:J)} -> #N/A | F25: {=LOOKUP(1,0/(('5.21出货明细'!X:X=$D$9)*('5.21出货明细'!A:A=A25)),'5.21出货明细'!L:L)} -> #N/A | G25: {=LOOKUP(1,0/(('5.21出货明细'!X:X=$D$9)*('5.21出货明细'!A:A=A25)),'5.21出货明细'!M:M)} -> #N/A | H25: {=LOOKUP(1,0/(('5.21出货明细'!X:X=$D$9)*('5.21出货明细'!A:A=A25)),'5.21出货明细'!P:P)} -> #N/A | I25: {=LOOKUP(1,0/(('5.21出货明细'!X:X=$D$9)*('5.21出货明细'!A:A=A25)),'5.21出货明细'!Q:Q)} -> #N/A | J25: {=LOOKUP(1,0/(('5.21出货明细'!X:X=$D$9)*('5.21出货明细'!A:A=A25)),'5.21出货明细'!AT:AT)} -> #N/A | K25: {=LOOKUP(1,0/(('5.21出货明细'!X:X=$D$9)*('5.21出货明细'!A:A=A25)),'5.21出货明细'!S:S)} -> #N/A
A26: 2 | B26: {=LOOKUP(1,0/(('5.21出货明细'!X:X=$D$9)*('5.21出货明细'!A:A=A26)),'5.21出货明细'!D:D)} -> #N/A | C26: {=LOOKUP(1,0/(('5.21出货明细'!X:X=$D$9)*('5.21出货明细'!A:A=A26)),'5.21出货明细'!G:G&'5.21出货明细'!F:F)} -> #N/A | D26: {=LOOKUP(1,0/(('5.21出货明细'!X:X=$D$9)*('5.21出货明细'!A:A=A26)),'5.21出货明细'!K:K)} -> #N/A | E26: {=LOOKUP(1,0/(('5.21出货明细'!X:X=$D$9)*('5.21出货明细'!A:A=A26)),'5.21出货明细'!J:J)} -> #N/A | F26: {=LOOKUP(1,0/(('5.21出货明细'!X:X=$D$9)*('5.21出货明细'!A:A=A26)),'5.21出货明细'!L:L)} -> #N/A | G26: {=LOOKUP(1,0/(('5.21出货明细'!X:X=$D$9)*('5.21出货明细'!A:A=A26)),'5.21出货明细'!M:M)} -> #N/A | H26: {=LOOKUP(1,0/(('5.21出货明细'!X:X=$D$9)*('5.21出货明细'!A:A=A26)),'5.21出货明细'!P:P)} -> #N/A | I26: {=LOOKUP(1,0/(('5.21出货明细'!X:X=$D$9)*('5.21出货明细'!A:A=A26)),'5.21出货明细'!Q:Q)} -> #N/A | J26: {=LOOKUP(1,0/(('5.21出货明细'!X:X=$D$9)*('5.21出货明细'!A:A=A26)),'5.21出货明细'!AT:AT)} -> #N/A | K26: {=LOOKUP(1,0/(('5.21出货明细'!X:X=$D$9)*('5.21出货明细'!A:A=A26)),'5.21出货明细'!S:S)} -> #N/A
A27: 3 | B27: {=LOOKUP(1,0/(('5.21出货明细'!X:X=$D$9)*('5.21出货明细'!A:A=A27)),'5.21出货明细'!D:D)} -> #N/A | C27: {=LOOKUP(1,0/(('5.21出货明细'!X:X=$D$9)*('5.21出货明细'!A:A=A27)),'5.21出货明细'!G:G&'5.21出货明细'!F:F)} -> #N/A | D27: {=LOOKUP(1,0/(('5.21出货明细'!X:X=$D$9)*('5.21出货明细'!A:A=A27)),'5.21出货明细'!K:K)} -> #N/A | E27: {=LOOKUP(1,0/(('5.21出货明细'!X:X=$D$9)*('5.21出货明细'!A:A=A27)),'5.21出货明细'!J:J)} -> #N/A | F27: {=LOOKUP(1,0/(('5.21出货明细'!X:X=$D$9)*('5.21出货明细'!A:A=A27)),'5.21出货明细'!L:L)} -> #N/A | G27: {=LOOKUP(1,0/(('5.21出货明细'!X:X=$D$9)*('5.21出货明细'!A:A=A27)),'5.21出货明细'!M:M)} -> #N/A | H27: {=LOOKUP(1,0/(('5.21出货明细'!X:X=$D$9)*('5.21出货明细'!A:A=A27)),'5.21出货明细'!P:P)} -> #N/A | I27: {=LOOKUP(1,0/(('5.21出货明细'!X:X=$D$9)*('5.21出货明细'!A:A=A27)),'5.21出货明细'!Q:Q)} -> #N/A | J27: {=LOOKUP(1,0/(('5.21出货明细'!X:X=$D$9)*('5.21出货明细'!A:A=A27)),'5.21出货明细'!AT:AT)} -> #N/A | K27: {=LOOKUP(1,0/(('5.21出货明细'!X:X=$D$9)*('5.21出货明细'!A:A=A27)),'5.21出货明细'!S:S)} -> #N/A
A28: 4 | B28: {=LOOKUP(1,0/(('5.21出货明细'!X:X=$D$9)*('5.21出货明细'!A:A=A28)),'5.21出货明细'!D:D)} -> #N/A | C28: {=LOOKUP(1,0/(('5.21出货明细'!X:X=$D$9)*('5.21出货明细'!A:A=A28)),'5.21出货明细'!G:G&'5.21出货明细'!F:F)} -> #N/A | D28: {=LOOKUP(1,0/(('5.21出货明细'!X:X=$D$9)*('5.21出货明细'!A:A=A28)),'5.21出货明细'!K:K)} -> #N/A | E28: {=LOOKUP(1,0/(('5.21出货明细'!X:X=$D$9)*('5.21出货明细'!A:A=A28)),'5.21出货明细'!J:J)} -> #N/A | F28: {=LOOKUP(1,0/(('5.21出货明细'!X:X=$D$9)*('5.21出货明细'!A:A=A28)),'5.21出货明细'!L:L)} -> #N/A | G28: {=LOOKUP(1,0/(('5.21出货明细'!X:X=$D$9)*('5.21出货明细'!A:A=A28)),'5.21出货明细'!M:M)} -> #N/A | H28: {=LOOKUP(1,0/(('5.21出货明细'!X:X=$D$9)*('5.21出货明细'!A:A=A28)),'5.21出货明细'!P:P)} -> #N/A | I28: {=LOOKUP(1,0/(('5.21出货明细'!X:X=$D$9)*('5.21出货明细'!A:A=A28)),'5.21出货明细'!Q:Q)} -> #N/A | J28: {=LOOKUP(1,0/(('5.21出货明细'!X:X=$D$9)*('5.21出货明细'!A:A=A28)),'5.21出货明细'!AT:AT)} -> #N/A | K28: {=LOOKUP(1,0/(('5.21出货明细'!X:X=$D$9)*('5.21出货明细'!A:A=A28)),'5.21出货明细'!S:S)} -> #N/A
A29: 5 | B29: {=LOOKUP(1,0/(('5.21出货明细'!X:X=$D$9)*('5.21出货明细'!A:A=A29)),'5.21出货明细'!D:D)} -> #N/A | C29: {=LOOKUP(1,0/(('5.21出货明细'!X:X=$D$9)*('5.21出货明细'!A:A=A29)),'5.21出货明细'!G:G&'5.21出货明细'!F:F)} -> #N/A | D29: {=LOOKUP(1,0/(('5.21出货明细'!X:X=$D$9)*('5.21出货明细'!A:A=A29)),'5.21出货明细'!K:K)} -> #N/A | E29: {=LOOKUP(1,0/(('5.21出货明细'!X:X=$D$9)*('5.21出货明细'!A:A=A29)),'5.21出货明细'!J:J)} -> #N/A | F29: {=LOOKUP(1,0/(('5.21出货明细'!X:X=$D$9)*('5.21出货明细'!A:A=A29)),'5.21出货明细'!L:L)} -> #N/A | G29: {=LOOKUP(1,0/(('5.21出货明细'!X:X=$D$9)*('5.21出货明细'!A:A=A29)),'5.21出货明细'!M:M)} -> #N/A | H29: {=LOOKUP(1,0/(('5.21出货明细'!X:X=$D$9)*('5.21出货明细'!A:A=A29)),'5.21出货明细'!P:P)} -> #N/A | I29: {=LOOKUP(1,0/(('5.21出货明细'!X:X=$D$9)*('5.21出货明细'!A:A=A29)),'5.21出货明细'!Q:Q)} -> #N/A | J29: {=LOOKUP(1,0/(('5.21出货明细'!X:X=$D$9)*('5.21出货明细'!A:A=A29)),'5.21出货明细'!AT:AT)} -> #N/A | K29: {=LOOKUP(1,0/(('5.21出货明细'!X:X=$D$9)*('5.21出货明细'!A:A=A29)),'5.21出货明细'!S:S)} -> #N/A
A30: 6 | B30: {=LOOKUP(1,0/(('5.21出货明细'!X:X=$D$9)*('5.21出货明细'!A:A=A30)),'5.21出货明细'!D:D)} -> #N/A | C30: {=LOOKUP(1,0/(('5.21出货明细'!X:X=$D$9)*('5.21出货明细'!A:A=A30)),'5.21出货明细'!G:G&'5.21出货明细'!F:F)} -> #N/A | D30: {=LOOKUP(1,0/(('5.21出货明细'!X:X=$D$9)*('5.21出货明细'!A:A=A30)),'5.21出货明细'!K:K)} -> #N/A | E30: {=LOOKUP(1,0/(('5.21出货明细'!X:X=$D$9)*('5.21出货明细'!A:A=A30)),'5.21出货明细'!J:J)} -> #N/A | F30: {=LOOKUP(1,0/(('5.21出货明细'!X:X=$D$9)*('5.21出货明细'!A:A=A30)),'5.21出货明细'!L:L)} -> #N/A | G30: {=LOOKUP(1,0/(('5.21出货明细'!X:X=$D$9)*('5.21出货明细'!A:A=A30)),'5.21出货明细'!M:M)} -> #N/A | H30: {=LOOKUP(1,0/(('5.21出货明细'!X:X=$D$9)*('5.21出货明细'!A:A=A30)),'5.21出货明细'!P:P)} -> #N/A | I30: {=LOOKUP(1,0/(('5.21出货明细'!X:X=$D$9)*('5.21出货明细'!A:A=A30)),'5.21出货明细'!Q:Q)} -> #N/A | J30: {=LOOKUP(1,0/(('5.21出货明细'!X:X=$D$9)*('5.21出货明细'!A:A=A30)),'5.21出货明细'!AT:AT)} -> #N/A | K30: {=LOOKUP(1,0/(('5.21出货明细'!X:X=$D$9)*('5.21出货明细'!A:A=A30)),'5.21出货明细'!S:S)} -> #N/A
A31: 7 | B31: {=LOOKUP(1,0/(('5.21出货明细'!X:X=$D$9)*('5.21出货明细'!A:A=A31)),'5.21出货明细'!D:D)} -> #N/A | C31: {=LOOKUP(1,0/(('5.21出货明细'!X:X=$D$9)*('5.21出货明细'!A:A=A31)),'5.21出货明细'!G:G&'5.21出货明细'!F:F)} -> #N/A | D31: {=LOOKUP(1,0/(('5.21出货明细'!X:X=$D$9)*('5.21出货明细'!A:A=A31)),'5.21出货明细'!K:K)} -> #N/A | E31: {=LOOKUP(1,0/(('5.21出货明细'!X:X=$D$9)*('5.21出货明细'!A:A=A31)),'5.21出货明细'!J:J)} -> #N/A | F31: {=LOOKUP(1,0/(('5.21出货明细'!X:X=$D$9)*('5.21出货明细'!A:A=A31)),'5.21出货明细'!L:L)} -> #N/A | G31: {=LOOKUP(1,0/(('5.21出货明细'!X:X=$D$9)*('5.21出货明细'!A:A=A31)),'5.21出货明细'!M:M)} -> #N/A | H31: {=LOOKUP(1,0/(('5.21出货明细'!X:X=$D$9)*('5.21出货明细'!A:A=A31)),'5.21出货明细'!P:P)} -> #N/A | I31: {=LOOKUP(1,0/(('5.21出货明细'!X:X=$D$9)*('5.21出货明细'!A:A=A31)),'5.21出货明细'!Q:Q)} -> #N/A | J31: {=LOOKUP(1,0/(('5.21出货明细'!X:X=$D$9)*('5.21出货明细'!A:A=A31)),'5.21出货明细'!AT:AT)} -> #N/A | K31: {=LOOKUP(1,0/(('5.21出货明细'!X:X=$D$9)*('5.21出货明细'!A:A=A31)),'5.21出货明细'!S:S)} -> #N/A
A32: 8 | B32: {=LOOKUP(1,0/(('5.21出货明细'!X:X=$D$9)*('5.21出货明细'!A:A=A32)),'5.21出货明细'!D:D)} -> #N/A | C32: {=LOOKUP(1,0/(('5.21出货明细'!X:X=$D$9)*('5.21出货明细'!A:A=A32)),'5.21出货明细'!G:G&'5.21出货明细'!F:F)} -> #N/A | D32: {=LOOKUP(1,0/(('5.21出货明细'!X:X=$D$9)*('5.21出货明细'!A:A=A32)),'5.21出货明细'!K:K)} -> #N/A | E32: {=LOOKUP(1,0/(('5.21出货明细'!X:X=$D$9)*('5.21出货明细'!A:A=A32)),'5.21出货明细'!J:J)} -> #N/A | F32: {=LOOKUP(1,0/(('5.21出货明细'!X:X=$D$9)*('5.21出货明细'!A:A=A32)),'5.21出货明细'!L:L)} -> #N/A | G32: {=LOOKUP(1,0/(('5.21出货明细'!X:X=$D$9)*('5.21出货明细'!A:A=A32)),'5.21出货明细'!M:M)} -> #N/A | H32: {=LOOKUP(1,0/(('5.21出货明细'!X:X=$D$9)*('5.21出货明细'!A:A=A32)),'5.21出货明细'!P:P)} -> #N/A | I32: {=LOOKUP(1,0/(('5.21出货明细'!X:X=$D$9)*('5.21出货明细'!A:A=A32)),'5.21出货明细'!Q:Q)} -> #N/A | J32: {=LOOKUP(1,0/(('5.21出货明细'!X:X=$D$9)*('5.21出货明细'!A:A=A32)),'5.21出货明细'!AT:AT)} -> #N/A | K32: {=LOOKUP(1,0/(('5.21出货明细'!X:X=$D$9)*('5.21出货明细'!A:A=A32)),'5.21出货明细'!S:S)} -> #N/A
A33: 9 | B33: {=LOOKUP(1,0/(('5.21出货明细'!X:X=$D$9)*('5.21出货明细'!A:A=A33)),'5.21出货明细'!D:D)} -> #N/A | C33: {=LOOKUP(1,0/(('5.21出货明细'!X:X=$D$9)*('5.21出货明细'!A:A=A33)),'5.21出货明细'!G:G&'5.21出货明细'!F:F)} -> #N/A | D33: {=LOOKUP(1,0/(('5.21出货明细'!X:X=$D$9)*('5.21出货明细'!A:A=A33)),'5.21出货明细'!K:K)} -> #N/A | E33: {=LOOKUP(1,0/(('5.21出货明细'!X:X=$D$9)*('5.21出货明细'!A:A=A33)),'5.21出货明细'!J:J)} -> #N/A | F33: {=LOOKUP(1,0/(('5.21出货明细'!X:X=$D$9)*('5.21出货明细'!A:A=A33)),'5.21出货明细'!L:L)} -> #N/A | G33: {=LOOKUP(1,0/(('5.21出货明细'!X:X=$D$9)*('5.21出货明细'!A:A=A33)),'5.21出货明细'!M:M)} -> #N/A | H33: {=LOOKUP(1,0/(('5.21出货明细'!X:X=$D$9)*('5.21出货明细'!A:A=A33)),'5.21出货明细'!P:P)} -> #N/A | I33: {=LOOKUP(1,0/(('5.21出货明细'!X:X=$D$9)*('5.21出货明细'!A:A=A33)),'5.21出货明细'!Q:Q)} -> #N/A | J33: {=LOOKUP(1,0/(('5.21出货明细'!X:X=$D$9)*('5.21出货明细'!A:A=A33)),'5.21出货明细'!AT:AT)} -> #N/A | K33: {=LOOKUP(1,0/(('5.21出货明细'!X:X=$D$9)*('5.21出货明细'!A:A=A33)),'5.21出货明细'!S:S)} -> #N/A
A34: 10 | B34: {=LOOKUP(1,0/(('5.21出货明细'!X:X=$D$9)*('5.21出货明细'!A:A=A34)),'5.21出货明细'!D:D)} -> #N/A | C34: {=LOOKUP(1,0/(('5.21出货明细'!X:X=$D$9)*('5.21出货明细'!A:A=A34)),'5.21出货明细'!G:G&'5.21出货明细'!F:F)} -> #N/A | D34: {=LOOKUP(1,0/(('5.21出货明细'!X:X=$D$9)*('5.21出货明细'!A:A=A34)),'5.21出货明细'!K:K)} -> #N/A | E34: {=LOOKUP(1,0/(('5.21出货明细'!X:X=$D$9)*('5.21出货明细'!A:A=A34)),'5.21出货明细'!J:J)} -> #N/A | F34: {=LOOKUP(1,0/(('5.21出货明细'!X:X=$D$9)*('5.21出货明细'!A:A=A34)),'5.21出货明细'!L:L)} -> #N/A | G34: {=LOOKUP(1,0/(('5.21出货明细'!X:X=$D$9)*('5.21出货明细'!A:A=A34)),'5.21出货明细'!M:M)} -> #N/A | H34: {=LOOKUP(1,0/(('5.21出货明细'!X:X=$D$9)*('5.21出货明细'!A:A=A34)),'5.21出货明细'!P:P)} -> #N/A | I34: {=LOOKUP(1,0/(('5.21出货明细'!X:X=$D$9)*('5.21出货明细'!A:A=A34)),'5.21出货明细'!Q:Q)} -> #N/A | J34: {=LOOKUP(1,0/(('5.21出货明细'!X:X=$D$9)*('5.21出货明细'!A:A=A34)),'5.21出货明细'!AT:AT)} -> #N/A | K34: {=LOOKUP(1,0/(('5.21出货明细'!X:X=$D$9)*('5.21出货明细'!A:A=A34)),'5.21出货明细'!S:S)} -> #N/A
A35: 11 | B35: {=LOOKUP(1,0/(('5.21出货明细'!X:X=$D$9)*('5.21出货明细'!A:A=A35)),'5.21出货明细'!D:D)} -> #N/A | C35: {=LOOKUP(1,0/(('5.21出货明细'!X:X=$D$9)*('5.21出货明细'!A:A=A35)),'5.21出货明细'!G:G&'5.21出货明细'!F:F)} -> #N/A | D35: {=LOOKUP(1,0/(('5.21出货明细'!X:X=$D$9)*('5.21出货明细'!A:A=A35)),'5.21出货明细'!K:K)} -> #N/A | E35: {=LOOKUP(1,0/(('5.21出货明细'!X:X=$D$9)*('5.21出货明细'!A:A=A35)),'5.21出货明细'!J:J)} -> #N/A | F35: {=LOOKUP(1,0/(('5.21出货明细'!X:X=$D$9)*('5.21出货明细'!A:A=A35)),'5.21出货明细'!L:L)} -> #N/A | G35: {=LOOKUP(1,0/(('5.21出货明细'!X:X=$D$9)*('5.21出货明细'!A:A=A35)),'5.21出货明细'!M:M)} -> #N/A | H35: {=LOOKUP(1,0/(('5.21出货明细'!X:X=$D$9)*('5.21出货明细'!A:A=A35)),'5.21出货明细'!P:P)} -> #N/A | I35: {=LOOKUP(1,0/(('5.21出货明细'!X:X=$D$9)*('5.21出货明细'!A:A=A35)),'5.21出货明细'!Q:Q)} -> #N/A | J35: {=LOOKUP(1,0/(('5.21出货明细'!X:X=$D$9)*('5.21出货明细'!A:A=A35)),'5.21出货明细'!AT:AT)} -> #N/A | K35: {=LOOKUP(1,0/(('5.21出货明细'!X:X=$D$9)*('5.21出货明细'!A:A=A35)),'5.21出货明细'!S:S)} -> #N/A
A36: 12 | B36: {=LOOKUP(1,0/(('5.21出货明细'!X:X=$D$9)*('5.21出货明细'!A:A=A36)),'5.21出货明细'!D:D)} -> #N/A | C36: {=LOOKUP(1,0/(('5.21出货明细'!X:X=$D$9)*('5.21出货明细'!A:A=A36)),'5.21出货明细'!G:G&'5.21出货明细'!F:F)} -> #N/A | D36: {=LOOKUP(1,0/(('5.21出货明细'!X:X=$D$9)*('5.21出货明细'!A:A=A36)),'5.21出货明细'!K:K)} -> #N/A | E36: {=LOOKUP(1,0/(('5.21出货明细'!X:X=$D$9)*('5.21出货明细'!A:A=A36)),'5.21出货明细'!J:J)} -> #N/A | F36: {=LOOKUP(1,0/(('5.21出货明细'!X:X=$D$9)*('5.21出货明细'!A:A=A36)),'5.21出货明细'!L:L)} -> #N/A | G36: {=LOOKUP(1,0/(('5.21出货明细'!X:X=$D$9)*('5.21出货明细'!A:A=A36)),'5.21出货明细'!M:M)} -> #N/A | H36: {=LOOKUP(1,0/(('5.21出货明细'!X:X=$D$9)*('5.21出货明细'!A:A=A36)),'5.21出货明细'!P:P)} -> #N/A | I36: {=LOOKUP(1,0/(('5.21出货明细'!X:X=$D$9)*('5.21出货明细'!A:A=A36)),'5.21出货明细'!Q:Q)} -> #N/A | J36: {=LOOKUP(1,0/(('5.21出货明细'!X:X=$D$9)*('5.21出货明细'!A:A=A36)),'5.21出货明细'!AT:AT)} -> #N/A | K36: {=LOOKUP(1,0/(('5.21出货明细'!X:X=$D$9)*('5.21出货明细'!A:A=A36)),'5.21出货明细'!S:S)} -> #N/A
... A42: 18 | B42: {=LOOKUP(1,0/(('5.21出货明细'!X:X=$D$9)*('5.21出货明细'!A:A=A42)),'5.21出货明细'!D:D)} -> #N/A | C42: {=LOOKUP(1,0/(('5.21出货明细'!X:X=$D$9)*('5.21出货明细'!A:A=A42)),'5.21出货明细'!G:G&'5.21出货明细'!F:F)} -> #N/A | D42: {=LOOKUP(1,0/(('5.21出货明细'!X:X=$D$9)*('5.21出货明细'!A:A=A42)),'5.21出货明细'!K:K)} -> #N/A | E42: {=LOOKUP(1,0/(('5.21出货明细'!X:X=$D$9)*('5.21出货明细'!A:A=A42)),'5.21出货明细'!J:J)} -> #N/A | F42: {=LOOKUP(1,0/(('5.21出货明细'!X:X=$D$9)*('5.21出货明细'!A:A=A42)),'5.21出货明细'!L:L)} -> #N/A | G42: {=LOOKUP(1,0/(('5.21出货明细'!X:X=$D$9)*('5.21出货明细'!A:A=A42)),'5.21出货明细'!M:M)} -> #N/A | H42: {=LOOKUP(1,0/(('5.21出货明细'!X:X=$D$9)*('5.21出货明细'!A:A=A42)),'5.21出货明细'!P:P)} -> #N/A | I42: {=LOOKUP(1,0/(('5.21出货明细'!X:X=$D$9)*('5.21出货明细'!A:A=A42)),'5.21出货明细'!Q:Q)} -> #N/A | J42: {=LOOKUP(1,0/(('5.21出货明细'!X:X=$D$9)*('5.21出货明细'!A:A=A42)),'5.21出货明细'!AT:AT)} -> #N/A | K42: {=LOOKUP(1,0/(('5.21出货明细'!X:X=$D$9)*('5.21出货明细'!A:A=A42)),'5.21出货明细'!S:S)} -> #N/A
D43: =SUM(D25:D42) -> #N/A | H43: =SUM(H25:H42) -> #N/A | I43: =SUM(I25:I42) -> #N/A | J43: =SUM(J25:J42) -> #N/A | K43: =SUM(K25:K42) -> #N/A
A46: ROYAL REGENT PRODUCTS INDUSTRIES LIMITED
A47: Unit 07-08,12/F,Greenfield Tower,Concordia Plaza,No.1 Science Museum Road,Tsim Sha Tsui,Kowloon,Postal Code:999077,Hong Kong
A51: PACKING LIST
A53: 1 .Shipper: | D53: 2. Packing List Number | H53: 3. Page
A54: ROYAL REGENT PRODUCTS INDUSTRIES LIMITED Unit 07-08,12/F,Greenfield Tower,Concordia Plaza,No.1 Science Museum Road,Tsim Sha Tsui,Kowloon,Postal Code:999077,Hong Kong | D54: =实业发票!H63 -> PR202600277
D55: 4. Packing List Date
...

Sheet 5.21出货明细
A3: 序号 serial number | B3: 中国HSCODE （China） | C3: 印尼HS CODE (Indonesia) | D3: 货号 Item No. | E3: 套公式名称栏 | F3: 产品中文名称 Chinese name of the product | G3: 产品英文名称 English name of the product | H3: 规格 specification | I3: 类别 kategori | J3: 单位 Unit | K3: 送货KG重量 Quantity | L3: 送货数量 Product quantity | M3: 单位 Unit | N3: 采购单价（换成港币） Purchase price | O3: 采购金额Purchase Amount | P3: 毛重总重 Total Gross weight（KGM） | Q3: 净重总重Total Net weight（KGM） | R3: 立方数/每箱CBM/Per carton | S3: 总立方数Total CBM | T3: 图片 Picture | U3: 产品用途 product use | V3: 合同号码 Contract No. | W3: 合同日期 Date of contract | X3: 发票号 Invoice No. | Y3: 发票日期 Date of Invoice | Z3: 发票单价 Unit price on invoice | AA3: 金额 Invoice amount | AB3: 发票合计金额Invoice total amount | AC3: 柜号 Container No. | AD3: 走柜日期 Shipping date | AE3: 提单号 Bl No. | AF3: 预计到港日期 ETA PORT | AG3: 实际到厂日期 Actual arrival date | AH3: Vessel Name/Voyage No. | AI3: 总集装箱运费金额（中国运费） Total Container Freight Amount (China's Freight) | AJ3: 货运代理运输费用 Forwarder Transportation Costs (Indonesia Freight) | AK3: Actual freight for product | AL3: 供应商 Supplier | AM3: 采购单日期 Date of purchase order | AN3: 采购单号 PO No. | AO3: 采购单价 Purchase price | AP3: 采购金额Purchase Amount | AQ3: 采购总额 Total Amount | AR3: 报关出口公司 | AS3: 提单抬头 | AT3: 箱数 Carton No. | AU3: 每箱数量 | AV3: 卡板 | AW3: 长 Length | AX3: 宽 Width | AY3: 高 Height | AZ3: 物料编码 | BA3: 使用部门 | BB3: 每箱重量 | BC3: 单个毛重 | BD3: 单个净重 | BE3: 备注
A4: 1 | B4: 9503009000 | C4: 392690 | D4: 721262-V2 | F4: 玩具配件包装扣 | G4: Plastic toy accessory packaging buckle | I4: 塑胶 | J4: KGM | K4: =52*2.03+1.74 -> 107.3 | L4: 111000 | M4: PCS | P4: =2.24*52+1.95 -> 118.43 | Q4: =K4 -> 107.3 | R4: =AW4*AX4*AY4/28316.75*0.0283 -> 0.010681628 | S4: =ROUND(R4*AT4,2) -> 0.57 | U4: 产品配件 | V4: RPIRRI260152 | W4: 46048 | X4: PR202600152 | Y4: 46048 | Z4: =AO4 -> 11 | AA4: =K4*Z4 -> 1180.3 | AL4: 华登（河源）玩具制品有限公司 | AM4: 46153 | AN4: E260420-06 | AO4: 11 | AP4: =AO4*K4 -> 1180.3 | AR4: 华登（河源）玩具制品有限公司 | AS4: 華登製品實業有限公司 | AT4: 53 | AU4: 2100pcs*52箱 1800pcs*1箱 | AW4: 27 | AX4: 14.5 | AY4: 27.3 | BB4: 2.24kg*52箱 1.95kg*1箱 | BC4: 0.001066 | BD4: =0.97/1000 -> 0.00097
A5: 2 | B5: 9503009000 | C5: 392690 | D5: 721262-V2 | F5: 玩具配件绑片 | G5: Plastic toy accessory binding pieces | I5: 塑胶 | J5: KGM | K5: =4.63*10 -> 46.3 | L5: 35000 | M5: PCS | P5: =5.01*10 -> 50.1 | Q5: =K5 -> 46.3 | R5: =AW5*AX5*AY5/28316.75*0.0283 -> 0.044220877 | S5: =ROUND(R5*AT5,2) -> 0.44 | U5: 产品配件 | V5: RPIRRI260152 | W5: 46048 | X5: PR202600152 | Y5: 46048 | Z5: =AO5 -> 5 | AA5: =K5*Z5 -> 231.5 | AL5: 华登（河源）玩具制品有限公司 | AM5: 46153 | AN5: E260420-06 | AO5: 5 | AP5: =AO5*K5 -> 231.5 | AR5: 华登（河源）玩具制品有限公司 | AS5: 華登製品實業有限公司 | AT5: 10 | AU5: 3500pcs | AW5: 53 | AX5: 28.3 | AY5: 29.5 | BB5: 5.01 | BC5: 0.001431 | BD5: =1.3/1000 -> 0.0013

Sheet 商品汇总表
A1: 商品编号 | B1: 商品名称 | D1: 货物品名及规格
A2: 8483409090 | B2: 0.37KW减速电机 | D2: 1|0|电磁感应定律|工业生产用|台成|YSF-71MI-4
A3: 8483409090 | B3: 0.55KW减速电机 | D3: 1|0|电磁感应定律|工业生产用|台成|YSF-80MI-4
A4: 5806109000 | B4: 1 1/2"黑色婴儿魔术贴（勾面） | D4: 0|0|织造方法：机织，起绒方式：绳绒|尼龙100%|幅宽：4-6
A5: 5806109000 | B5: 1 1/2"黑色婴儿魔术贴（毛面） | D5: 0|0|织造方法：机织，起绒方式：绳绒|尼龙100%|幅宽：4-6
A6: 5808100000 | B6: 1"黑色涤纶带PANTONE Black C（100Y/卷） | D6: 0|0|成卷|100%涤纶|
A7: 5808100000 | B7: 1"绿色树叶花边3500C | D7: 0|0|成卷|100%涤纶|
A8: 5808100000 | B8: 1.25"黑色半圆花边 | D8: 0|0|成卷|100%涤纶|
A9: 5806109000 | B9: 1.5"黑色魔术贴（勾） | D9: 0|0|织造方法：机织，起绒方式：绳绒|尼龙100%|幅宽：4-6
A10: 5806109000 | B10: 1.5"黑色魔术贴（毛） | D10: 0|0|织造方法：机织，起绒方式：绳绒|尼龙100%|幅宽：4-6
A11: 5806320000 | B11: 1.6CM白色背胶魔术贴
A12: 5808100000 | B12: 1/2"黑色丝带PANTONE Black 6 C（50Y/卷） | D12: 0|0|成卷|100%涤纶|
A13: 5806320000 | B13: 1/4"白色普通棉带（700Y/卷） | D13: 0|0|成卷|100%涤纶|
A14: 5808100000 | B14: 1/4"白色丈根（100Y/卷） | D14: 0|0|织造方法：机织，经编|涤纶100%|幅宽：63
A15: 5806320000 | B15: 1/4"粉色丝带PANTONE 1905 C | D15: 0|0|成卷|100%涤纶|
A16: 5808100000 | B16: 1/4"黑色涤纶带PANTONE Black 6 C（100Y/卷） | D16: 0|0|成卷|100%涤纶|
A17: 5808100000 | B17: 1/4"黑色色丁丝带（25Y/卷） | D17: 0|0|成卷|100%涤纶|
A18: 5808100000 | B18: 1/4"黑色丝带PANTONE Black 6 C（25Y/卷 | D18: 0|0|成卷|100%涤纶|
A19: 5808100000 | B19: 1/4"黑色丈根（100Y/卷） | D19: 0|0|织造方法：机织，经编|涤纶100%|幅宽：63
A20: 5808100000 | B20: 1/4"黄色色丁丝带PANTONE 144 C（25Y/卷） | D20: 0|0|成卷|100%涤纶|
A21: 5808100000 | B21: 1/4"金色葱带（200Y/卷） | D21: 0|0|成卷|100%涤纶|
A22: 5806320000 | B22: 1/4"蓝色丝带PANTONE 2146 C | D22: 0|0|成卷|100%涤纶|
A23: 5808100000 | B23: 1/4"绿色丝带PANTONE 3500 C | D23: 0|0|成卷|100%涤纶|
A24: 5808100090 | B24: 1/8"白色丈根
A25: 5808100000 | B25: 1/8"黑色丈根（145Y/卷） | D25: 0|0|成卷|涤纶+橡胶|
A26: 5806109000 | B26: 2"白色魔术贴（勾） | D26: 0|0|织造方法：机织，起绒方式：绳绒|尼龙100%|幅宽：4-6
A27: 5806109000 | B27: 2"白色魔术贴（毛） | D27: 0|0|织造方法：机织，起绒方式：绳绒|尼龙100%|幅宽：4-6
A28: 5806109000 | B28: 2"黑色魔术贴（勾） | D28: 0|0|织造方法：机织，起绒方式：绳绒|尼龙100%|幅宽：4-6
A29: 5806109000 | B29: 2"黑色魔术贴（毛） | D29: 0|0|织造方法：机织，起绒方式：绳绒|尼龙100%|幅宽：4-6
A30: 5808100000 | B30: 2"黑色针织松紧 | D30: 0|0|成卷|100%涤纶|
A31: 8479899990 | B31: 2.6自动螺丝机 | D31: 1|0|工业装螺丝用|自动筛选出不合格的螺丝|ANSHUN|AS-900
A32: 4819100000 | B32: 20155371-GEN发光飞碟彩卡 | D32: 0|0|瓦楞纸制|可折叠
A33: 4819100000 | B33: 20156724 GEN 红色彩卡 | D33: 0|0|瓦楞纸制|可折叠
A34: 4819100000 | B34: 20156733 GML 黄色彩卡 | D34: 0|0|瓦楞纸制|可折叠
A35: 4819100000 | B35: 20156801 GEN 红色彩卡 | D35: 0|0|瓦楞纸制|可折叠
A36: 4819100000 | B36: 20156803 GEN彩卡 | D36: 0|0|瓦楞纸制|可折叠
